Workbook

Sheet 14C
A1: core | B1: depth_top | C1: depth_bottom | D1: depth_mid | E1: cal.age | F1: cal.age.err | G1: mat.dated | H1: 14C.raw | I1: 14C.raw_err | J1: Labcode | K1: D14C | L1: D14C.err
A2: LPAZ-21P | B2: 63 | C2: 65 | D2: =AVERAGE(B2:C2) -> 64 | E2: =VLOOKUP(D2,agemodels!$A$3:$E$265,4,0) -> 11738.5 | F2: =VLOOKUP(D2,agemodels!$A$3:$F$265,6,0) -> 586.22449 | G2: Planulina ariminensis | H2: 15620 | I2: 100 | J2: 162173 | K2: =((EXP(-(H2)/8033)/EXP(-($E2)/8267))-1)*1000 -> -408.18219 | L2: =((EXP(-(H2-I2)/8033)/EXP(-($E2)/8267))-1)*1000-K2 -> 7.41338
A3: LPAZ-21P | B3: 66 | C3: 67 | D3: =AVERAGE(B3:C3) -> 66.5 | E3: =VLOOKUP(D3,agemodels!$A$3:$E$265,4,0) -> 12821 | F3: =VLOOKUP(D3,agemodels!$A$3:$F$265,6,0) -> 187.19388 | G3: Planulina ariminensis | H3: 16880 | I3: 650 | J3: 178177 | K3: =((EXP(-(H3)/8033)/EXP(-($E3)/8267))-1)*1000 -> -423.31963 | L3: =((EXP(-(H3-I3)/8033)/EXP(-($E3)/8267))-1)*1000-K3 -> 48.602652
A4: LPAZ-21P | B4: 67 | C4: 68 | D4: =AVERAGE(B4:C4) -> 67.5 | E4: =VLOOKUP(D4,agemodels!$A$3:$E$265,4,0) -> 13096.2 | F4: =VLOOKUP(D4,agemodels!$A$3:$F$265,6,0) -> 125.79082 | G4: Planulina ariminensis | H4: 16555 | I4: 45 | J4: 206073 | K4: =((EXP(-(H4)/8033)/EXP(-($E4)/8267))-1)*1000 -> -379.18369 | L4: =((EXP(-(H4-I4)/8033)/EXP(-($E4)/8267))-1)*1000-K4 -> 3.4875053
A5: LPAZ-21P | B5: 68 | C5: 69 | D5: =AVERAGE(B5:C5) -> 68.5 | E5: =VLOOKUP(D5,agemodels!$A$3:$E$265,4,0) -> 13276.9 | F5: =VLOOKUP(D5,agemodels!$A$3:$F$265,6,0) -> 202.57653 | G5: Planulina ariminensis | H5: 14330 | I5: 60 | J5: 206075 | K5: =((EXP(-(H5)/8033)/EXP(-($E5)/8267))-1)*1000 -> -162.9568 | L5: =((EXP(-(H5-I5)/8033)/EXP(-($E5)/8267))-1)*1000-K5 -> 6.2754414
A6: LPAZ-21P | B6: 69 | C6: 70.5 | D6: =AVERAGE(B6:C6) -> 69.75 | E6: =VLOOKUP(C6,agemodels!$A$3:$E$265,4,0) -> 13690.9 | F6: =VLOOKUP(C6,agemodels!$A$3:$F$265,6,0) -> 297.83163 | G6: Planulina ariminensis | H6: 15120 | I6: 90 | J6: 175820 | K6: =((EXP(-(H6)/8033)/EXP(-($E6)/8267))-1)*1000 -> -202.3978 | L6: =((EXP(-(H6-I6)/8033)/EXP(-($E6)/8267))-1)*1000-K6 -> 8.98641
A7: LPAZ-21P | B7: 70.5 | C7: 71.5 | D7: =AVERAGE(B7:C7) -> 71 | E7: =VLOOKUP(D7,agemodels!$A$3:$E$265,4,0) -> 13791.5 | F7: =VLOOKUP(D7,agemodels!$A$3:$F$265,6,0) -> 325.20408 | G7: Planulina ariminensis | H7: 15375 | I7: 45 | J7: 203474 | K7: =((EXP(-(H7)/8033)/EXP(-($E7)/8267))-1)*1000 -> -217.85919 | L7: =((EXP(-(H7-I7)/8033)/EXP(-($E7)/8267))-1)*1000-K7 -> 4.3937637
A8: LPAZ-21P | B8: 71.5 | C8: 72.5 | D8: =AVERAGE(B8:C8) -> 72 | E8: =VLOOKUP(D8,agemodels!$A$3:$E$265,4,0) -> 14001.9 | F8: =VLOOKUP(D8,agemodels!$A$3:$F$265,6,0) -> 344.61735 | G8: Planulina ariminensis | H8: 15395 | I8: 40 | J8: 203476 | K8: =((EXP(-(H8)/8033)/EXP(-($E8)/8267))-1)*1000 -> -199.69281 | L8: =((EXP(-(H8-I8)/8033)/EXP(-($E8)/8267))-1)*1000-K8 -> 3.9950358
A9: LPAZ-21P | B9: 72 | C9: 73 | D9: =AVERAGE(B9:C9) -> 72.5 | E9: =VLOOKUP(D9,agemodels!$A$3:$E$265,4,0) -> 14108.9 | F9: =VLOOKUP(D9,agemodels!$A$3:$F$265,6,0) -> 350.7398 | G9: Planulina ariminensis | H9: 17080 | I9: 330 | J9: 203478 | K9: =((EXP(-(H9)/8033)/EXP(-($E9)/8267))-1)*1000 -> -342.67476 | L9: =((EXP(-(H9-I9)/8033)/EXP(-($E9)/8267))-1)*1000-K9 -> 27.565606
A10: LPAZ-21P | B10: 73 | C10: 74 | D10: =AVERAGE(B10:C10) -> 73.5 | E10: =VLOOKUP(D10,agemodels!$A$3:$E$265,4,0) -> 14314.9 | F10: =VLOOKUP(D10,agemodels!$A$3:$F$265,6,0) -> 368.41837 | G10: Planulina ariminensis | H10: 16110 | I10: 70 | J10: 203480 | K10: =((EXP(-(H10)/8033)/EXP(-($E10)/8267))-1)*1000 -> -239.59652 | L10: =((EXP(-(H10-I10)/8033)/EXP(-($E10)/8267))-1)*1000-K10 -> 6.6551519
A11: LPAZ-21P | B11: 74 | C11: 76 | D11: =AVERAGE(B11:C11) -> 75 | E11: =VLOOKUP(D11,agemodels!$A$3:$E$265,4,0) -> 14629.5 | F11: =VLOOKUP(D11,agemodels!$A$3:$F$265,6,0) -> 399.20918 | G11: Planulina ariminensis | H11: 15965 | I11: 45 | J11: 181567 | K11: =((EXP(-(H11)/8033)/EXP(-($E11)/8267))-1)*1000 -> -195.71423 | L11: =((EXP(-(H11-I11)/8033)/EXP(-($E11)/8267))-1)*1000-K11 -> 4.5181655
A12: LPAZ-21P | B12: 75 | C12: 76 | D12: =AVERAGE(B12:C12) -> 75.5 | E12: =VLOOKUP(D12,agemodels!$A$3:$E$265,4,0) -> 14734.3 | F12: =VLOOKUP(D12,agemodels!$A$3:$F$265,6,0) -> 396.70918 | G12: Planulina ariminensis | H12: 15660 | I12: 35 | J12: 204764 | K12: =((EXP(-(H12)/8033)/EXP(-($E12)/8267))-1)*1000 -> -153.93184 | L12: =((EXP(-(H12-I12)/8033)/EXP(-($E12)/8267))-1)*1000-K12 -> 3.6943845
A13: LPAZ-21P | B13: 77 | C13: 78 | D13: =AVERAGE(B13:C13) -> 77.5 | E13: =VLOOKUP(D13,agemodels!$A$3:$E$265,4,0) -> 15156.9 | F13: =VLOOKUP(D13,agemodels!$A$3:$F$265,6,0) -> 412.88265 | G13: Planulina ariminensis | H13: 16775 | I13: 45 | J13: 203058 | K13: =((EXP(-(H13)/8033)/EXP(-($E13)/8267))-1)*1000 -> -224.95864 | L13: =((EXP(-(H13-I13)/8033)/EXP(-($E13)/8267))-1)*1000-K13 -> 4.3538817
A14: LPAZ-21P | B14: 77 | C14: 79 | D14: =AVERAGE(B14:C14) -> 78 | E14: =VLOOKUP(D14,agemodels!$A$3:$E$265,4,0) -> 15258.4 | F14: =VLOOKUP(D14,agemodels!$A$3:$F$265,6,0) -> 424.03061 | G14: Planulina ariminensis | H14: 16760 | I14: 70 | J14: 175789 | K14: =((EXP(-(H14)/8033)/EXP(-($E14)/8267))-1)*1000 -> -213.91776 | L14: =((EXP(-(H14-I14)/8033)/EXP(-($E14)/8267))-1)*1000-K14 -> 6.8798959
A15: LPAZ-21P | B15: 78 | C15: 79 | D15: =AVERAGE(B15:C15) -> 78.5 | E15: =VLOOKUP(D15,agemodels!$A$3:$E$265,4,0) -> 15363.7 | F15: =VLOOKUP(D15,agemodels!$A$3:$F$265,6,0) -> 416.96429 | G15: Planulina ariminensis | H15: 17020 | I15: 60 | J15: 206076 | K15: =((EXP(-(H15)/8033)/EXP(-($E15)/8267))-1)*1000 -> -229.19739 | L15: =((EXP(-(H15-I15)/8033)/EXP(-($E15)/8267))-1)*1000-K15 -> 5.7788255
A16: LPAZ-21P | B16: 79 | C16: 81 | D16: =AVERAGE(B16:C16) -> 80 | E16: =VLOOKUP(D16,agemodels!$A$3:$E$265,4,0) -> 15687.2 | F16: =VLOOKUP(D16,agemodels!$A$3:$F$265,6,0) -> 433.13776 | G16: Planulina ariminensis | H16: 16550 | I16: 45 | J16: 181535 | K16: =((EXP(-(H16)/8033)/EXP(-($E16)/8267))-1)*1000 -> -150.13929 | L16: =((EXP(-(H16-I16)/8033)/EXP(-($E16)/8267))-1)*1000-K16 -> 4.7741878
A17: LPAZ-21P | B17: 80 | C17: 81 | D17: =AVERAGE(B17:C17) -> 80.5 | E17: =VLOOKUP(D17,agemodels!$A$3:$E$265,4,0) -> 15796.1 | F17: =VLOOKUP(D17,agemodels!$A$3:$F$265,6,0) -> 422.95918 | G17: Planulina ariminensis | H17: 15920 | I17: 100 | J17: 206078 | K17: =((EXP(-(H17)/8033)/EXP(-($E17)/8267))-1)*1000 -> -68.615853 | L17: =((EXP(-(H17-I17)/8033)/EXP(-($E17)/8267))-1)*1000-K17 -> 11.666943
A18: LPAZ-21P | B18: 82 | C18: 84 | D18: =AVERAGE(B18:C18) -> 83 | E18: =VLOOKUP(D18,agemodels!$A$3:$E$265,4,0) -> 16311.5 | F18: =VLOOKUP(D18,agemodels!$A$3:$F$265,6,0) -> 421.07143 | G18: Planulina ariminensis | H18: 17520 | I18: 80 | J18: 175800 | K18: =((EXP(-(H18)/8033)/EXP(-($E18)/8267))-1)*1000 -> -187.72603 | L18: =((EXP(-(H18-I18)/8033)/EXP(-($E18)/8267))-1)*1000-K18 -> 8.1297858
A19: LPAZ-21P | B19: 84.5 | C19: 85.5 | D19: =AVERAGE(B19:C19) -> 85 | E19: =VLOOKUP(D19,agemodels!$A$3:$E$265,4,0) -> 16724.2 | F19: =VLOOKUP(D19,agemodels!$A$3:$F$265,6,0) -> 390.84184 | G19: Planulina ariminensis | H19: 16640 | I19: 140 | J19: 178190 | K19: =((EXP(-(H19)/8033)/EXP(-($E19)/8267))-1)*1000 -> -47.293226 | L19: =((EXP(-(H19-I19)/8033)/EXP(-($E19)/8267))-1)*1000-K19 -> 16.749409
A20: LPAZ-21P | B20: 85.5 | C20: 87 | D20: =AVERAGE(B20:C20) -> 86.25 | E20: =VLOOKUP(C20,agemodels!$A$3:$E$265,4,0) -> 17125.4 | F20: =VLOOKUP(C20,agemodels!$A$3:$F$265,6,0) -> 356.65816 | G20: Planulina ariminensis | H20: 17760 | I20: 60 | J20: 181548 | K20: =((EXP(-(H20)/8033)/EXP(-($E20)/8267))-1)*1000 -> -130.07013 | L20: =((EXP(-(H20-I20)/8033)/EXP(-($E20)/8267))-1)*1000-K20 -> 6.5219978
A21: LPAZ-21P | B21: 87 | C21: 87.5 | D21: =AVERAGE(B21:C21) -> 87.25 | E21: =VLOOKUP(C21,agemodels!$A$3:$E$265,4,0) -> 17231.5 | F21: =VLOOKUP(C21,agemodels!$A$3:$F$265,6,0) -> 324.13265 | G21: Planulina ariminensis | H21: 17615 | I21: 50 | J21: 181536 | K21: =((EXP(-(H21)/8033)/EXP(-($E21)/8267))-1)*1000 -> -102.7834 | L21: =((EXP(-(H21-I21)/8033)/EXP(-($E21)/8267))-1)*1000-K21 -> 5.6019836
A22: LPAZ-21P | B22: 87.5 | C22: 88 | D22: =AVERAGE(B22:C22) -> 87.75 | E22: =VLOOKUP(C22,agemodels!$A$3:$E$265,4,0) -> 17343.8 | F22: =VLOOKUP(C22,agemodels!$A$3:$F$265,6,0) -> 313.69898 | G22: Planulina ariminensis | H22: 17350 | I22: 70 | J22: 201575 | K22: =((EXP(-(H22)/8033)/EXP(-($E22)/8267))-1)*1000 -> -60.008954 | L22: =((EXP(-(H22-I22)/8033)/EXP(-($E22)/8267))-1)*1000-K22 -> 8.2269261
A23: LPAZ-21P | B23: 88 | C23: 89 | D23: =AVERAGE(B23:C23) -> 88.5 | E23: =VLOOKUP(D23,agemodels!$A$3:$E$265,4,0) -> 17549.2 | F23: =VLOOKUP(D23,agemodels!$A$3:$F$265,6,0) -> 292.62755 | G23: Planulina ariminensis | H23: 17610 | I23: 60 | J23: 201577 | K23: =((EXP(-(H23)/8033)/EXP(-($E23)/8267))-1)*1000 -> -67.051843 | L23: =((EXP(-(H23-I23)/8033)/EXP(-($E23)/8267))-1)*1000-K23 -> 6.9944556
A24: LPAZ-21P | B24: 89 | C24: 90 | D24: =AVERAGE(B24:C24) -> 89.5 | E24: =VLOOKUP(D24,agemodels!$A$3:$E$265,4,0) -> 17922.4 | F24: =VLOOKUP(D24,agemodels!$A$3:$F$265,6,0) -> 351.5051 | G24: Planulina ariminensis | H24: 18140 | I24: 60 | J24: 183754 | K24: =((EXP(-(H24)/8033)/EXP(-($E24)/8267))-1)*1000 -> -86.288265 | L24: =((EXP(-(H24-I24)/8033)/EXP(-($E24)/8267))-1)*1000-K24 -> 6.8502372
A25: LPAZ-21P | B25: 90 | C25: 91 | D25: =AVERAGE(B25:C25) -> 90.5 | E25: =VLOOKUP(D25,agemodels!$A$3:$E$265,4,0) -> 18266.8 | F25: =VLOOKUP(D25,agemodels!$A$3:$F$265,6,0) -> 396.04592 | G25: Planulina ariminensis | H25: 18190 | I25: 450 | J25: 203049 | K25: =((EXP(-(H25)/8033)/EXP(-($E25)/8267))-1)*1000 -> -53.330137 | L25: =((EXP(-(H25-I25)/8033)/EXP(-($E25)/8267))-1)*1000-K25 -> 54.544936
A26: LPAZ-21P | B26: 91 | C26: 92 | D26: =AVERAGE(B26:C26) -> 91.5 | E26: =VLOOKUP(D26,agemodels!$A$3:$E$265,4,0) -> 18611.8 | F26: =VLOOKUP(D26,agemodels!$A$3:$F$265,6,0) -> 427.09184 | G26: Planulina ariminensis | H26: 19220 | I26: 450 | J26: 201581 | K26: =((EXP(-(H26)/8033)/EXP(-($E26)/8267))-1)*1000 -> -131.76578 | L26: =((EXP(-(H26-I26)/8033)/EXP(-($E26)/8267))-1)*1000-K26 -> 50.025655
A27: LPAZ-21P | B27: 92 | C27: 93 | D27: =AVERAGE(B27:C27) -> 92.5 | E27: =VLOOKUP(D27,agemodels!$A$3:$E$265,4,0) -> 18977.8 | F27: =VLOOKUP(D27,agemodels!$A$3:$F$265,6,0) -> 439.61735 | G27: Planulina ariminensis | H27: 16800 | I27: 70 | J27: 201583 | K27: =((EXP(-(H27)/8033)/EXP(-($E27)/8267))-1)*1000 -> 226.58755 | L27: =((EXP(-(H27-I27)/8033)/EXP(-($E27)/8267))-1)*1000-K27 -> 10.735257
A28: LPAZ-21P | B28: 92 | C28: 94 | D28: =AVERAGE(B28:C28) -> 93 | E28: =VLOOKUP(D28,agemodels!$A$3:$E$265,4,0) -> 19161.2 | F28: =VLOOKUP(D28,agemodels!$A$3:$F$265,6,0) -> 466.70918 | G28: Planulina ariminensis | H28: 16805 | I28: 45 | J28: 181538 | K28: =((EXP(-(H28)/8033)/EXP(-($E28)/8267))-1)*1000 -> 253.32262 | L28: =((EXP(-(H28-I28)/8033)/EXP(-($E28)/8267))-1)*1000-K28 -> 7.0406803
A29: LPAZ-21P | B29: 93 | C29: 94 | D29: =AVERAGE(B29:C29) -> 93.5 | E29: =VLOOKUP(D29,agemodels!$A$3:$E$265,4,0) -> 19326.3 | F29: =VLOOKUP(D29,agemodels!$A$3:$F$265,6,0) -> 453.67347 | G29: Planulina ariminensis | H29: 16530 | I29: 60 | J29: 201588 | K29: =((EXP(-(H29)/8033)/EXP(-($E29)/8267))-1)*1000 -> 323.13361 | L29: =((EXP(-(H29-I29)/8033)/EXP(-($E29)/8267))-1)*1000-K29 -> 9.9197359
A30: LPAZ-21P | B30: 94 | C30: 95 | D30: =AVERAGE(B30:C30) -> 94.5 | E30: =VLOOKUP(D30,agemodels!$A$3:$E$265,4,0) -> 19670 | F30: =VLOOKUP(D30,agemodels!$A$3:$F$265,6,0) -> 460.35714 | G30: Planulina ariminensis | H30: 16960 | I30: 100 | J30: 192493 | K30: =((EXP(-(H30)/8033)/EXP(-($E30)/8267))-1)*1000 -> 307.4107 | L30: =((EXP(-(H30-I30)/8033)/EXP(-($E30)/8267))-1)*1000-K30 -> 16.377223
A31: LPAZ-21P | B31: 96 | C31: 97 | D31: =AVERAGE(B31:C31) -> 96.5 | E31: =VLOOKUP(D31,agemodels!$A$3:$E$265,4,0) -> 21733.8 | F31: =VLOOKUP(D31,agemodels!$A$3:$F$265,6,0) -> 391.86224 | G31: Planulina ariminensis | H31: 20240 | I31: 70 | J31: 181551 | K31: =((EXP(-(H31)/8033)/EXP(-($E31)/8267))-1)*1000 -> 115.58182 | L31: =((EXP(-(H31-I31)/8033)/EXP(-($E31)/8267))-1)*1000-K31 -> 9.7637198
A32: LPAZ-21P | B32: 97 | C32: 98 | D32: =AVERAGE(B32:C32) -> 97.5 | E32: =VLOOKUP(D32,agemodels!$A$3:$E$265,4,0) -> 22709.2 | F32: =VLOOKUP(D32,agemodels!$A$3:$F$265,6,0) -> 304.15816 | G32: Planulina ariminensis | H32: 19580 | I32: 670 | J32: 200178 | K32: =((EXP(-(H32)/8033)/EXP(-($E32)/8267))-1)*1000 -> 362.77675 | L32: =((EXP(-(H32-I32)/8033)/EXP(-($E32)/8267))-1)*1000-K32 -> 118.53838
A33: LPAZ-21P | B33: 97 | C33: 99 | D33: =AVERAGE(B33:C33) -> 98 | E33: =VLOOKUP(D33,agemodels!$A$3:$E$265,4,0) -> 22809.2 | F33: =VLOOKUP(D33,agemodels!$A$3:$F$265,6,0) -> 319.77041 | G33: Planulina ariminensis | H33: 20196.667 | I33: 263.33333 | J33: 178194, 181540 | K33: =((EXP(-(H33)/8033)/EXP(-($E33)/8267))-1)*1000 -> 277.43474 | L33: =((EXP(-(H33-I33)/8033)/EXP(-($E33)/8267))-1)*1000-K33 -> 42.570097
A34: LPAZ-21P | B34: 98 | C34: 99 | D34: =AVERAGE(B34:C34) -> 98.5 | E34: =VLOOKUP(D34,agemodels!$A$3:$E$265,4,0) -> 22898.9 | F34: =VLOOKUP(D34,agemodels!$A$3:$F$265,6,0) -> 302.52551 | G34: Planulina ariminensis | H34: 20240 | I34: 260 | J34: 200181 | K34: =((EXP(-(H34)/8033)/EXP(-($E34)/8267))-1)*1000 -> 284.42341 | L34: =((EXP(-(H34-I34)/8033)/EXP(-($E34)/8267))-1)*1000-K34 -> 42.252367
A35: LPAZ-21P | B35: 99 | C35: 100 | D35: =AVERAGE(B35:C35) -> 99.5 | E35: =VLOOKUP(D35,agemodels!$A$3:$E$265,4,0) -> 23072.9 | F35: =VLOOKUP(D35,agemodels!$A$3:$F$265,6,0) -> 298.57143 | G35: Planulina ariminensis | H35: 20490 | I35: 160 | J35: 200525 | K35: =((EXP(-(H35)/8033)/EXP(-($E35)/8267))-1)*1000 -> 271.54898 | L35: =((EXP(-(H35-I35)/8033)/EXP(-($E35)/8267))-1)*1000-K35 -> 25.580415
A36: LPAZ-21P | B36: 100 | C36: 101 | D36: =AVERAGE(B36:C36) -> 100.5 | E36: =VLOOKUP(D36,agemodels!$A$3:$E$265,4,0) -> 23256 | F36: =VLOOKUP(D36,agemodels!$A$3:$F$265,6,0) -> 278.34184 | G36: Planulina ariminensis | H36: 20630 | I36: 120 | J36: 200527 | K36: =((EXP(-(H36)/8033)/EXP(-($E36)/8267))-1)*1000 -> 277.56512 | L36: =((EXP(-(H36-I36)/8033)/EXP(-($E36)/8267))-1)*1000-K36 -> 19.228012
A37: LPAZ-21P | B37: 101 | C37: 102 | D37: =AVERAGE(B37:C37) -> 101.5 | E37: =VLOOKUP(D37,agemodels!$A$3:$E$265,4,0) -> 23438.1 | F37: =VLOOKUP(D37,agemodels!$A$3:$F$265,6,0) -> 255.20408 | G37: Planulina ariminensis | H37: 20630 | I37: 80 | J37: 181554 | K37: =((EXP(-(H37)/8033)/EXP(-($E37)/8267))-1)*1000 -> 306.01871 | L37: =((EXP(-(H37-I37)/8033)/EXP(-($E37)/8267))-1)*1000-K37 -> 13.071516
A38: LPAZ-21P | B38: 104 | C38: 106 | D38: =AVERAGE(B38:C38) -> 105 | E38: =VLOOKUP(D38,agemodels!$A$3:$E$265,4,0) -> 24297.8 | F38: =VLOOKUP(D38,agemodels!$A$3:$F$265,6,0) -> 296.37755 | G38: Planulina ariminensis | H38: 21520 | I38: 80 | J38: 176294 | K38: =((EXP(-(H38)/8033)/EXP(-($E38)/8267))-1)*1000 -> 297.16635 | L38: =((EXP(-(H38-I38)/8033)/EXP(-($E38)/8267))-1)*1000-K38 -> 12.982916
A39: LPAZ-21P | B39: 110 | C39: 111 | D39: =AVERAGE(B39:C39) -> 110.5 | E39: =VLOOKUP(D39,agemodels!$A$3:$E$265,4,0) -> 25927.6 | F39: =VLOOKUP(D39,agemodels!$A$3:$F$265,6,0) -> 370.58673 | G39: Planulina ariminensis | H39: 22660 | I39: 90 | J39: 201590 | K39: =((EXP(-(H39)/8033)/EXP(-($E39)/8267))-1)*1000 -> 370.82511 | L39: =((EXP(-(H39-I39)/8033)/EXP(-($E39)/8267))-1)*1000-K39 -> 15.444787
A40: LPAZ-21P | B40: 114 | C40: 115 | D40: =AVERAGE(B40:C40) -> 114.5 | E40: =VLOOKUP(D40,agemodels!$A$3:$E$265,4,0) -> 27223.4 | F40: =VLOOKUP(D40,agemodels!$A$3:$F$265,6,0) -> 541.9898 | G40: Planulina ariminensis | H40: 25490 | I40: 80 | J40: 204773 | K40: =((EXP(-(H40)/8033)/EXP(-($E40)/8267))-1)*1000 -> 127.33871 | L40: =((EXP(-(H40-I40)/8033)/EXP(-($E40)/8267))-1)*1000-K40 -> 11.283166
...

Sheet agemodels
A1: LPAZ21P_0to131B.csv (YEARS BP) | I1: ET97-7T
A2: depth | B2: min | C2: max | D2: median | E2: wmean | F2: stdev | G2: stdev | I2: depth | J2: min | K2: max | L2: median | M2: wmean | N2: stdev
A3: 0 | B3: -977.6 | C3: 4071.6 | D3: 234.4 | E3: 550.3 | F3: =(C3-B3)/(2*1.96) -> 1288.0612 | G3: =ABS(E3-C3)/1.96 -> 1796.5816 | I3: 70 | J3: 11951.8 | K3: 13188.8 | L3: 12607.8 | M3: 12603.4 | N3: =(K3-J3)/(2*1.96) -> 315.56122
A4: 0.5 | B4: -919.8 | C4: 4143.9 | D4: 311.3 | E4: 631.3 | F4: =(C4-B4)/(2*1.96) -> 1291.7602 | G4: =ABS(E4-C4)/1.96 -> 1792.1429 | I4: 70.5 | J4: 11982.9 | K4: 13209.9 | L4: 12633.8 | M4: 12628.7 | N4: =(K4-J4)/(2*1.96) -> 313.0102
A5: 1 | B5: -874.6 | C5: 4224.2 | D5: 405.1 | E5: 726.6 | F5: =(C5-B5)/(2*1.96) -> 1300.7143 | G5: =ABS(E5-C5)/1.96 -> 1784.4898 | I5: 71 | J5: 12008.4 | K5: 13232.4 | L5: 12658.6 | M5: 12653.6 | N5: =(K5-J5)/(2*1.96) -> 312.2449
A6: 1.5 | B6: -794.5 | C6: 4306.8 | D6: 496.9 | E6: 822.4 | F6: =(C6-B6)/(2*1.96) -> 1301.352 | G6: =ABS(E6-C6)/1.96 -> 1777.7551 | I6: 71.5 | J6: 12037.8 | K6: 13255.9 | L6: 12682.8 | M6: 12678.5 | N6: =(K6-J6)/(2*1.96) -> 310.7398
A7: 2 | B7: -744.2 | C7: 4389.8 | D7: 593.5 | E7: 918 | F7: =(C7-B7)/(2*1.96) -> 1309.6939 | G7: =ABS(E7-C7)/1.96 -> 1771.3265 | I7: 72 | J7: 12062.7 | K7: 13279.9 | L7: 12706.8 | M7: 12703.1 | N7: =(K7-J7)/(2*1.96) -> 310.5102
A8: 2.5 | B8: -661.7 | C8: 4469.4 | D8: 688.9 | E8: 1005.2 | F8: =(C8-B8)/(2*1.96) -> 1308.9541 | G8: =ABS(E8-C8)/1.96 -> 1767.449 | I8: 72.5 | J8: 12096.7 | K8: 13304.6 | L8: 12734.6 | M8: 12729.9 | N8: =(K8-J8)/(2*1.96) -> 308.13776
A9: 3 | B9: -603 | C9: 4541.3 | D9: 784.9 | E9: 1092.5 | F9: =(C9-B9)/(2*1.96) -> 1312.3214 | G9: =ABS(E9-C9)/1.96 -> 1759.5918 | I9: 73 | J9: 12124.7 | K9: 13332.6 | L9: 12762 | M9: 12756.6 | N9: =(K9-J9)/(2*1.96) -> 308.13776
A10: 3.5 | B10: -526.7 | C10: 4607.7 | D10: 880.1 | E10: 1176.2 | F10: =(C10-B10)/(2*1.96) -> 1309.7959 | G10: =ABS(E10-C10)/1.96 -> 1750.7653 | I10: 73.5 | J10: 12146.7 | K10: 13354.6 | L10: 12786 | M10: 12781.3 | N10: =(K10-J10)/(2*1.96) -> 308.13776
A11: 4 | B11: -460.6 | C11: 4667.2 | D11: 970.2 | E11: 1260.5 | F11: =(C11-B11)/(2*1.96) -> 1308.1122 | G11: =ABS(E11-C11)/1.96 -> 1738.1122 | I11: 74 | J11: 12172.6 | K11: 13378.5 | L11: 12813 | M11: 12808.3 | N11: =(K11-J11)/(2*1.96) -> 307.62755
A12: 4.5 | B12: -382.2 | C12: 4715.1 | D12: 1049.5 | E12: 1336.8 | F12: =(C12-B12)/(2*1.96) -> 1300.3316 | G12: =ABS(E12-C12)/1.96 -> 1723.6224 | I12: 74.5 | J12: 12205 | K12: 13398.1 | L12: 12838 | M12: 12833.8 | N12: =(K12-J12)/(2*1.96) -> 304.36224
A13: 5 | B13: -319.7 | C13: 4780.3 | D13: 1127.7 | E13: 1413.1 | F13: =(C13-B13)/(2*1.96) -> 1301.0204 | G13: =ABS(E13-C13)/1.96 -> 1717.9592 | I13: 75 | J13: 12230.7 | K13: 13423.6 | L13: 12864.7 | M13: 12859.8 | N13: =(K13-J13)/(2*1.96) -> 304.31122
A14: 5.5 | B14: -239 | C14: 4845 | D14: 1209.3 | E14: 1490.7 | F14: =(C14-B14)/(2*1.96) -> 1296.9388 | G14: =ABS(E14-C14)/1.96 -> 1711.3776 | I14: 75.5 | J14: 12263.6 | K14: 13445.7 | L14: 12890.1 | M14: 12885.6 | N14: =(K14-J14)/(2*1.96) -> 301.55612
... A133: 65 | B133: 11125.9 | C133: 12863.6 | D133: 12208.1 | E133: 12158 | F133: =(C133-B133)/(2*1.96) -> 443.29082 | G133: =ABS(E133-C133)/1.96 -> 360 | I133: 135 | J133: 19001.6 | K133: 19486.7 | L133: 19211.4 | M133: 19222.8 | N133: =(K133-J133)/(2*1.96) -> 123.75
A134: 65.5 | B134: 11493.4 | C134: 12919.3 | D134: 12421.3 | E134: 12368.4 | F134: =(C134-B134)/(2*1.96) -> 363.75 | G134: =ABS(E134-C134)/1.96 -> 281.07143
A135: 66 | B135: 11718.4 | C135: 13037.4 | D135: 12656.5 | E135: 12579.1 | F135: =(C135-B135)/(2*1.96) -> 336.47959 | G135: =ABS(E135-C135)/1.96 -> 233.82653
A136: 66.5 | B136: 12338.6 | C136: 13072.4 | D136: 12821 | E136: 12790.9 | F136: =(C136-B136)/(2*1.96) -> 187.19388 | G136: =ABS(E136-C136)/1.96 -> 143.62245
A137: 67 | B137: 12808.3 | C137: 13167.8 | D137: 13007.3 | E137: 13006 | F137: =(C137-B137)/(2*1.96) -> 91.709184 | G137: =ABS(E137-C137)/1.96 -> 82.55102
A138: 67.5 | B138: 12873 | C138: 13366.1 | D138: 13096.2 | E138: 13106.2 | F138: =(C138-B138)/(2*1.96) -> 125.79082 | G138: =ABS(E138-C138)/1.96 -> 132.60204
A139: 68 | B139: 12904.9 | C139: 13655 | D139: 13170.6 | E139: 13203.3 | F139: =(C139-B139)/(2*1.96) -> 191.35204 | G139: =ABS(E139-C139)/1.96 -> 230.45918
A140: 68.5 | B140: 12976.8 | C140: 13770.9 | D140: 13276.9 | E140: 13307.6 | F140: =(C140-B140)/(2*1.96) -> 202.57653 | G140: =ABS(E140-C140)/1.96 -> 236.37755
A141: 69 | B141: 13016.6 | C141: 13983 | D141: 13378 | E141: 13414.4 | F141: =(C141-B141)/(2*1.96) -> 246.53061 | G141: =ABS(E141-C141)/1.96 -> 290.10204
A142: 69.5 | B142: 13096.8 | C142: 14106.3 | D142: 13484.1 | E142: 13520.1 | F142: =(C142-B142)/(2*1.96) -> 257.52551 | G142: =ABS(E142-C142)/1.96 -> 299.08163
A143: 70 | B143: 13146.8 | C143: 14286.3 | D143: 13584.8 | E143: 13625.4 | F143: =(C143-B143)/(2*1.96) -> 290.68878 | G143: =ABS(E143-C143)/1.96 -> 337.19388
A144: 70.5 | B144: 13230.3 | C144: 14397.8 | D144: 13690.9 | E144: 13728.5 | F144: =(C144-B144)/(2*1.96) -> 297.83163 | G144: =ABS(E144-C144)/1.96 -> 341.47959
A145: 71 | B145: 13279.8 | C145: 14554.6 | D145: 13791.5 | E145: 13828.9 | F145: =(C145-B145)/(2*1.96) -> 325.20408 | G145: =ABS(E145-C145)/1.96 -> 370.2551
... A265: 131 | B265: 29952.9 | C265: 34715.8 | D265: 33537.5 | E265: 33068.9 | F265: =(C265-B265)/(2*1.96) -> 1215.0255 | G265: =ABS(E265-C265)/1.96 -> 840.2551
