Workbook

Sheet 14C
Q1: NEW DATA | R1: P.arimensis | S1: P.arimensis | T1: P.arimensis | U1: G.bulloides | V1: G.bulloides | W1: G.bulloides
A2: core | B2: depth_top | C2: depth_bottom | D2: depth_mid | E2: cal.age | F2: cal.age.err | G2: mat.dated | H2: 14C.raw | I2: 14C.raw_err | J2: Labcode | K2: D14C | L2: D14C.err | O2: depth_top | P2: depth_bot | Q2: depth_mid | R2: 14C.age | S2: 14C.age.err | T2: 14C.ID | U2: 14C.age | V2: 14C.age.err | W2: 14C.ID
A3: LPAZ-21P | B3: 63 | C3: 65 | D3: 64 | E3: 11738.5 | F3: 586.22449 | G3: Planulina ariminensis | H3: 15620 | I3: 100 | J3: 162173 | K3: -408.18219 | L3: 7.41338 | O3: 106 | P3: 108 | Q3: 107 | R3: 22570 | S3: 80 | T3: 208195 | U3: 19310 | V3: 140 | W3: 176732
A4: LPAZ-21P | B4: 66 | C4: 67 | D4: 66.5 | E4: 12821 | F4: 187.19388 | G4: Planulina ariminensis | H4: 16880 | I4: 650 | J4: 178177 | K4: -423.31963 | L4: 48.602652 | O4: 121 | P4: 122 | Q4: 121.5 | R4: 28880 | S4: 550 | T4: 233855 | U4: 27400 | V4: 120 | W4: 233854
A5: LPAZ-21P | B5: 67 | C5: 68 | D5: 67.5 | E5: 13096.2 | F5: 125.79082 | G5: Planulina ariminensis | H5: 16555 | I5: 45 | J5: 206073 | K5: -379.18369 | L5: 3.4875053 | O5: 122 | P5: 124 | Q5: 123 | R5: 28440 | S5: 420 | T5: 176317 | U5: 26560 | V5: 550 | W5: 175258
A6: LPAZ-21P | B6: 68 | C6: 69 | D6: 68.5 | E6: 13276.9 | F6: 202.57653 | G6: Planulina ariminensis | H6: 14330 | I6: 60 | J6: 206075 | K6: -162.9568 | L6: 6.2754414 | O6: 130 | P6: 131 | Q6: 130.5 | R6: 30670 | S6: 760 | T6: 177344 | U6: 33070 | V6: 180 | W6: 203485
A7: LPAZ-21P | B7: 69 | C7: 70.5 | D7: 69.75 | E7: 13690.9 | F7: 297.83163 | G7: Planulina ariminensis | H7: 15120 | I7: 90 | J7: 175820 | K7: -202.3978 | L7: 8.98641
A8: LPAZ-21P | B8: 70.5 | C8: 71.5 | D8: 71 | E8: 13791.5 | F8: 325.20408 | G8: Planulina ariminensis | H8: 15375 | I8: 45 | J8: 203474 | K8: -217.85919 | L8: 4.3937637
A9: LPAZ-21P | B9: 71.5 | C9: 72.5 | D9: 72 | E9: 14001.9 | F9: 344.61735 | G9: Planulina ariminensis | H9: 15395 | I9: 40 | J9: 203476 | K9: -199.69281 | L9: 3.9950358
A10: LPAZ-21P | B10: 72 | C10: 73 | D10: 72.5 | E10: 14108.9 | F10: 350.7398 | G10: Planulina ariminensis | H10: 17080 | I10: 330 | J10: 203478 | K10: -342.67476 | L10: 27.565606
A11: LPAZ-21P | B11: 73 | C11: 74 | D11: 73.5 | E11: 14314.9 | F11: 368.41837 | G11: Planulina ariminensis | H11: 16110 | I11: 70 | J11: 203480 | K11: -239.59652 | L11: 6.6551519
A12: LPAZ-21P | B12: 74 | C12: 76 | D12: 75 | E12: 14629.5 | F12: 399.20918 | G12: Planulina ariminensis | H12: 15965 | I12: 45 | J12: 181567 | K12: -195.71423 | L12: 4.5181655
A13: LPAZ-21P | B13: 75 | C13: 76 | D13: 75.5 | E13: 14734.3 | F13: 396.70918 | G13: Planulina ariminensis | H13: 15660 | I13: 35 | J13: 204764 | K13: -153.93184 | L13: 3.6943845
A14: LPAZ-21P | B14: 77 | C14: 78 | D14: 77.5 | E14: 15156.9 | F14: 412.88265 | G14: Planulina ariminensis | H14: 16775 | I14: 45 | J14: 203058 | K14: -224.95864 | L14: 4.3538817
A15: LPAZ-21P | B15: 77 | C15: 79 | D15: 78 | E15: 15258.4 | F15: 424.03061 | G15: Planulina ariminensis | H15: 16760 | I15: 70 | J15: 175789 | K15: -213.91776 | L15: 6.8798959
A16: LPAZ-21P | B16: 78 | C16: 79 | D16: 78.5 | E16: 15363.7 | F16: 416.96429 | G16: Planulina ariminensis | H16: 17020 | I16: 60 | J16: 206076 | K16: -229.19739 | L16: 5.7788255
A17: LPAZ-21P | B17: 79 | C17: 81 | D17: 80 | E17: 15687.2 | F17: 433.13776 | G17: Planulina ariminensis | H17: 16550 | I17: 45 | J17: 181535 | K17: -150.13929 | L17: 4.7741878
A18: LPAZ-21P | B18: 80 | C18: 81 | D18: 80.5 | E18: 15796.1 | F18: 422.95918 | G18: Planulina ariminensis | H18: 15920 | I18: 100 | J18: 206078 | K18: -68.615853 | L18: 11.666943
... A33: LPAZ-21P | B33: 97 | C33: 98 | D33: 97.5 | E33: 22709.2 | F33: 304.15816 | G33: Planulina ariminensis | H33: 19580 | I33: 670 | J33: 200178 | K33: 362.77675 | L33: 118.53838
A34: LPAZ-21P | B34: 97 | C34: 99 | D34: 98 | E34: 22809.2 | F34: 319.77041 | G34: Planulina ariminensis | H34: 20196.667 | I34: 263.33333 | J34: 178194, 181540 | K34: 277.43474 | L34: 42.570097
A35: LPAZ-21P | B35: 98 | C35: 99 | D35: 98.5 | E35: 22898.9 | F35: 302.52551 | G35: Planulina ariminensis | H35: 20240 | I35: 260 | J35: 200181 | K35: 284.42341 | L35: 42.252367
A36: LPAZ-21P | B36: 99 | C36: 100 | D36: 99.5 | E36: 23072.9 | F36: 298.57143 | G36: Planulina ariminensis | H36: 20490 | I36: 160 | J36: 200525 | K36: 271.54898 | L36: 25.580415
A37: LPAZ-21P | B37: 100 | C37: 101 | D37: 100.5 | E37: 23256 | F37: 278.34184 | G37: Planulina ariminensis | H37: 20630 | I37: 120 | J37: 200527 | K37: 277.56512 | L37: 19.228012
A38: LPAZ-21P | B38: 101 | C38: 102 | D38: 101.5 | E38: 23438.1 | F38: 255.20408 | G38: Planulina ariminensis | H38: 20630 | I38: 80 | J38: 181554 | K38: 306.01871 | L38: 13.071516
A39: LPAZ-21P | B39: 104 | C39: 106 | D39: 105 | E39: 24297.8 | F39: 296.37755 | G39: Planulina ariminensis | H39: 21520 | I39: 80 | J39: 176294 | K39: 297.16635 | L39: 12.982916
A40: LPAZ-21P | B40: 110 | C40: 111 | D40: 110.5 | E40: 25927.6 | F40: 370.58673 | G40: Planulina ariminensis | H40: 22660 | I40: 90 | J40: 201590 | K40: 370.82511 | L40: 15.444787
A41: LPAZ-21P | B41: 114 | C41: 115 | D41: 114.5 | E41: 27223.4 | F41: 541.9898 | G41: Planulina ariminensis | H41: 25490 | I41: 80 | J41: 204773 | K41: 127.33871 | L41: 11.283166
A42: LPAZ-21P | B42: 115 | C42: 116 | D42: 115.5 | E42: 27573.8 | F42: 586.14796 | G42: Planulina ariminensis | H42: 25590 | I42: 100 | J42: 204776 | K42: 161.5978 | L42: 14.550704
A43: LPAZ-21P | B43: 116 | C43: 117 | D43: 116.5 | E43: 27914.6 | F43: 619.94898 | G43: Planulina ariminensis | H43: 27020 | I43: 190 | J43: 206080 | K43: 13.08986 | L43: 24.247669
A44: LPAZ-21P | B44: 116 | C44: 118 | D44: 117 | E44: 28090 | F44: 650.15306 | G44: Planulina ariminensis | H44: 26540 | I44: 410 | J44: 176296 | K44: 98.532646 | L44: 57.524026
A45: LPAZ-21P | B45: 117 | C45: 118 | D45: 117.5 | E45: 28278.8 | F45: 653.52041 | G45: Planulina ariminensis | H45: 26190 | I45: 160 | J45: 206085 | K45: 173.96087 | L45: 23.617184
A46: LPAZ-21P | B46: 119 | C46: 120 | D46: 119.5 | E46: 28982 | F46: 767.32143 | G46: Planulina ariminensis | H46: 27410 | I46: 780 | J46: 177324 | K46: 98.088518 | L46: 111.97206
A47: LPAZ-21P | B47: 122 | C47: 124 | D47: 123 | E47: 30259.7 | F47: 972.47449 | G47: Planulina ariminensis | H47: 28440 | I47: 420 | J47: 176317 | K47: 127.38875 | L47: 60.512916
A48: LPAZ-21P | B48: 2 | C48: 3 | D48: 2.5 | E48: 5428.3 | F48: 370.35 | G48: Uvigerina peregrina | H48: 5831.6667 | I48: 58.333333 | J48: 157540, 157542, 157543 | K48: -66.991545 | L48: 6.7998984
A49: LPAZ-21P | B49: 22 | C49: 24 | D49: 23 | E49: 6803.4 | F49: 161.75 | G49: Uvigerina peregrina | H49: 7215 | I49: 20 | J49: 160284 | K49: -72.452522 | L49: 2.3122199
A50: LPAZ-21P | B50: 42 | C50: 44 | D50: 43 | E50: 7987.6 | F50: 102.8 | G50: Uvigerina peregrina | H50: 8425 | I50: 22.5 | J50: 160293, 176715 | K50: -79.276707 | L50: 2.5825114
A51: LPAZ-21P | B51: 46 | C51: 48 | D51: 47 | E51: 8175.2 | F51: 168 | G51: Uvigerina peregrina | H51: 9185 | I51: 25 | J51: 176718 | K51: -143.1675 | L51: 2.6707556
A52: LPAZ-21P | B52: 48 | C52: 50 | D52: 49 | E52: 8263.2 | F52: 189.45 | G52: Uvigerina peregrina | H52: 8865 | I52: 35 | J52: 176280 | K52: -98.803921 | L52: 3.9351023
A53: LPAZ-21P | B53: 52 | C53: 55 | D53: 53.5 | E53: 8465.8 | F53: 200.6 | G53: Uvigerina peregrina | H53: 9075 | I53: 35 | J53: 176282 | K53: -100.27625 | L53: 3.9286734
A54: LPAZ-21P | B54: 57 | C54: 59 | D54: 58 | E54: 8665.5 | F54: 168.9 | G54: Uvigerina peregrina | H54: 9077.5 | I54: 30 | J54: 176284, 181565 | K54: -78.564446 | L54: 3.4476222
...

Sheet d11B
A1: Delta pH | B1: Delta pKB | C1: - | D1: log10 | E1: d11B SW | F1: d11B SW.err | G1: d11B1 | H1: d11B0 | I1: alpha | J1: epsilon
E2: 39.61 | F2: 4.2 | I2: 1.0272 | J2: 27.2
I5: Planulina ariminensis | AD5: planktic foram G. bulloides
A6: analysis_date | B6: depth | D6: d11B | E6: flag | F6: d11B_2sigma | G6: cal.age | H6: cal.age.err | I6: 14C age | J6: 14C.age.err | K6: AMS# | L6: D14C | M6: D14C.err | N6: D(temp) | O6: pKB | P6: D(pKB) | Q6: Delta(pH) pt 1 | R6: Delta(pH) pt 2 | S6: Delta(pH) | T6: Delta(pH)? | U6: Note: | V6: cal.age.rnd | W6: D14C.atmos | X6: D14C.err.atmos | Y6: DD14C | Z6: DD14C.err | AD6: analysis_date | AE6: depth | AF6: d11B | AG6: B [ppb] | AH6: d11B_2sigma | AI6: mgca | AJ6: mgca_2sigma
A7: 20221219 | B7: 63 | D7: 15.819844 | F7: 0.14 | G7: =VLOOKUP(B7,'14C'!B$3:L$47,4,0) -> 11738.5 | H7: =VLOOKUP(B7,'14C'!B$3:L$47,5) -> 586.22449 | I7: =VLOOKUP(B7,'14C'!B$3:L$47,7,0) -> 15620 | J7: =VLOOKUP(B7,'14C'!B$3:L$47,8,0) -> 100 | K7: =VLOOKUP(B7,'14C'!B$3:L$47,9,0) -> 162173 | L7: =VLOOKUP(B7,'14C'!B$3:L$47,10,0) -> -408.18219 | M7: =VLOOKUP(B7,'14C'!B$3:L$47,11,0)*1 -> 7.41338 | N7: =VLOOKUP(MROUND(G7,200),MOT!B$3:C$1502,2)*1 -> -0.088108 | O7: =pKB!G67 -> 8.6003597 | P7: =(pKB!G$32-d11B!O7) -> 0.035334199 | Q7: =((D$16-D7)/(E$2-(I$2*D7)-J$2)) -> 0.0066837334 | R7: =(((I$2-1)*E$2-J$2)/(D$16-E$2)) -> 1.0968594 | S7: =P7-LOG(1+(Q7*R7)) -> 0.03216195 | T7: =P7-LOG((1+((D7-D$16)/(E$2-(I$2*d11B!D7)-J$2))*(((I$2-1)*(E$2-J$2))/d11B!D16-E$2))) -> -0.066618922 | V7: =MROUND(G7,10) -> 11740 | W7: =VLOOKUP(V7,'co2'!A$7:E$9999,4,0) -> 176.7 | X7: =VLOOKUP(V7,'co2'!A$7:E$9999,5,0) -> 3.3 | Y7: =W7-L7 -> 584.88219 | Z7: =(M7^2+X7^2)^0.5 -> 8.1146905 | AD7: 20180709 | AE7: 72 | AF7: 17.787443 | AG7: 16.993656 | AH7: 0.2913634 | AI7: 3.5794618 | AJ7: 0.042953542
A8: 20221219 | B8: 67 | D8: 15.689512 | F8: 0.14 | G8: =VLOOKUP(B8,'14C'!B$3:L$47,4,0) -> 13096.2 | H8: =VLOOKUP(B8,'14C'!B$3:L$47,5) -> 125.79082 | I8: =VLOOKUP(B8,'14C'!B$3:L$47,7,0) -> 16555 | J8: =VLOOKUP(B8,'14C'!B$3:L$47,8,0) -> 45 | K8: =VLOOKUP(B8,'14C'!B$3:L$47,9,0) -> 206073 | L8: =VLOOKUP(B8,'14C'!B$3:L$47,10,0) -> -379.18369 | M8: =VLOOKUP(B8,'14C'!B$3:L$47,11,0) -> 3.4875053 | N8: =VLOOKUP(MROUND(G8,200),MOT!B$3:C$1502,2)*1 -> -1.2555 | O8: =pKB!G79 -> 8.6144934 | P8: =(pKB!G$32-d11B!O8) -> 0.021200519 | Q8: =((D$16-D8)/(E$2-(I$2*D8)-J$2)) -> -0.028240342 | R8: =(((I$2-1)*E$2-J$2)/(D$16-E$2)) -> 1.0968594 | S8: =P8-LOG(1+(Q8*R8)) -> 0.034865844 | T8: =P8-LOG((1+((D8-D$16)/(E$2-(I$2*d11B!D8)-J$2))*(((I$2-1)*(E$2-J$2))/d11B!D17-E$2))) -> #NUM! | V8: =MROUND(G8,10) -> 13100 | W8: =VLOOKUP(V8,'co2'!A$7:E$9999,4,0) -> 211.2 | X8: =VLOOKUP(V8,'co2'!A$7:E$9999,5,0) -> 4.5 | Y8: =W8-L8 -> 590.38369 | Z8: =(M8^2+X8^2)^0.5 -> 5.6932146 | AD8: 20180709 | AE8: 73 | AF8: 18.220424 | AG8: 15.927419 | AH8: 0.3203902 | AI8: 3.9342706 | AJ8: 0.047211247
A9: 20221219 | B9: 67 | D9: 15.787392 | F9: 0.14 | G9: =VLOOKUP(B9,'14C'!B$3:L$47,4,0) -> 13096.2 | H9: =VLOOKUP(B9,'14C'!B$3:L$47,5) -> 125.79082 | I9: =VLOOKUP(B9,'14C'!B$3:L$47,7,0) -> 16555 | J9: =VLOOKUP(B9,'14C'!B$3:L$47,8,0) -> 45 | K9: =VLOOKUP(B9,'14C'!B$3:L$47,9,0) -> 206073 | L9: =VLOOKUP(B9,'14C'!B$3:L$47,10,0) -> -379.18369 | M9: =VLOOKUP(B9,'14C'!B$3:L$47,11,0) -> 3.4875053 | N9: =VLOOKUP(MROUND(G9,200),MOT!B$3:C$1502,2)*1 -> -1.2555 | O9: =O8 -> 8.6144934 | P9: =(pKB!G$32-d11B!O9) -> 0.021200519 | Q9: =((D$16-D9)/(E$2-(I$2*D9)-J$2)) -> -0.0017826481 | R9: =(((I$2-1)*E$2-J$2)/(D$16-E$2)) -> 1.0968594 | S9: =P9-LOG(1+(Q9*R9)) -> 0.022050533 | T9: =P9-LOG((1+((D9-D$16)/(E$2-(I$2*d11B!D9)-J$2))*(((I$2-1)*(E$2-J$2))/d11B!D18-E$2))) -> 0.052984257 | V9: =MROUND(G9,10) -> 13100 | W9: =VLOOKUP(V9,'co2'!A$7:E$9999,4,0) -> 211.2 | X9: =VLOOKUP(V9,'co2'!A$7:E$9999,5,0) -> 4.5 | Y9: =W9-L9 -> 590.38369 | Z9: =(M9^2+X9^2)^0.5 -> 5.6932146 | AD9: 20180709 | AE9: 79 | AF9: 17.897187 | AG9: 12.407348 | AH9: 0.4147743 | AI9: 3.5986162 | AJ9: 0.043183395
A10: 20180711 | B10: 69 | D10: 15.778169 | F10: 0.2632985 | G10: =VLOOKUP(B10,'14C'!B$3:L$47,4,0) -> 13690.9 | H10: =VLOOKUP(B10,'14C'!B$3:L$47,5) -> 297.83163 | I10: =VLOOKUP(B10,'14C'!B$3:L$47,7,0) -> 15120 | J10: =VLOOKUP(B10,'14C'!B$3:L$47,8,0) -> 90 | K10: =VLOOKUP(B10,'14C'!B$3:L$47,9,0) -> 175820 | L10: =VLOOKUP(B10,'14C'!B$3:L$47,10,0) -> -202.3978 | M10: =VLOOKUP(B10,'14C'!B$3:L$47,11,0) -> 8.98641 | N10: =VLOOKUP(MROUND(G10,200),MOT!B$3:C$1502,2)*1 -> -1.2433 | O10: =pKB!G78 -> 8.6133156 | P10: =(pKB!G$32-d11B!O10) -> 0.022378326 | Q10: =((D$16-D10)/(E$2-(I$2*D10)-J$2)) -> -0.0042156676 | R10: =(((I$2-1)*E$2-J$2)/(D$16-E$2)) -> 1.0968594 | S10: =P10-LOG(1+(Q10*R10)) -> 0.024391159 | T10: =P10-LOG((1+((D10-D$16)/(E$2-(I$2*d11B!D10)-J$2))*(((I$2-1)*(E$2-J$2))/d11B!D19-E$2))) -> 0.10167778 | V10: =MROUND(G10,10) -> 13690 | W10: =VLOOKUP(V10,'co2'!A$7:E$9999,4,0) -> 200.3 | X10: =VLOOKUP(V10,'co2'!A$7:E$9999,5,0) -> 3.8 | Y10: =W10-L10 -> 402.6978 | Z10: =(M10^2+X10^2)^0.5 -> 9.7568215 | AD10: 20221219 | AE10: 87 | AF10: 17.975221 | AH10: 0.14 | AI10: 3.8174977 | AJ10: 0.045809973
A11: 20180711 | B11: 72 | D11: 16.097482 | F11: 0.2536396 | G11: =VLOOKUP(B11,'14C'!B$3:L$47,4,0) -> 14108.9 | H11: =VLOOKUP(B11,'14C'!B$3:L$47,5) -> 350.7398 | I11: =VLOOKUP(B11,'14C'!B$3:L$47,7,0) -> 17080 | J11: =VLOOKUP(B11,'14C'!B$3:L$47,8,0) -> 330 | K11: =VLOOKUP(B11,'14C'!B$3:L$47,9,0) -> 203478 | L11: =VLOOKUP(B11,'14C'!B$3:L$47,10,0) -> -342.67476 | M11: =VLOOKUP(B11,'14C'!B$3:L$47,11,0) -> 27.565606 | N11: =VLOOKUP(MROUND(G11,200),MOT!B$3:C$1502,2)*1 -> -1.2533 | O11: =O9 -> 8.6144934 | P11: =(pKB!G$32-d11B!O11) -> 0.021200519 | Q11: =((D$16-D11)/(E$2-(I$2*D11)-J$2)) -> 0.073522261 | R11: =(((I$2-1)*E$2-J$2)/(D$16-E$2)) -> 1.0968594 | S11: =P11-LOG(1+(Q11*R11)) -> -0.012481959 | T11: =P11-LOG((1+((D11-D$16)/(E$2-(I$2*d11B!D11)-J$2))*(((I$2-1)*(E$2-J$2))/d11B!D20-E$2))) -> -0.57104763 | V11: =MROUND(G11,10) -> 14110 | W11: =VLOOKUP(V11,'co2'!A$7:E$9999,4,0) -> 200.9 | X11: =VLOOKUP(V11,'co2'!A$7:E$9999,5,0) -> 3.5 | Y11: =W11-L11 -> 543.57476 | Z11: =(M11^2+X11^2)^0.5 -> 27.786915 | AD11: 20180709 | AE11: 97 | AG11: 10.493146 | AI11: 3.4606578 | AJ11: 0.041527893
A12: 20180711 | B12: 73 | D12: 15.634219 | F12: 0.2570814 | G12: =VLOOKUP(B12,'14C'!B$3:L$47,4,0) -> 14314.9 | H12: =VLOOKUP(B12,'14C'!B$3:L$47,5) -> 368.41837 | I12: =VLOOKUP(B12,'14C'!B$3:L$47,7,0) -> 16110 | J12: =VLOOKUP(B12,'14C'!B$3:L$47,8,0) -> 70 | K12: =VLOOKUP(B12,'14C'!B$3:L$47,9,0) -> 203480 | L12: =VLOOKUP(B12,'14C'!B$3:L$47,10,0) -> -239.59652 | M12: =VLOOKUP(B12,'14C'!B$3:L$47,11,0) -> 6.6551519 | N12: =VLOOKUP(MROUND(G12,200),MOT!B$3:C$1502,2)*1 -> -1.0909 | O12: =pKB!G77 -> 8.6121377 | P12: =(pKB!G$32-d11B!O12) -> 0.023556133 | Q12: =((D$16-D12)/(E$2-(I$2*D12)-J$2)) -> -0.043830674 | R12: =(((I$2-1)*E$2-J$2)/(D$16-E$2)) -> 1.0968594 | S12: =P12-LOG(1+(Q12*R12)) -> 0.044953896 | T12: =P12-LOG((1+((D12-D$16)/(E$2-(I$2*d11B!D12)-J$2))*(((I$2-1)*(E$2-J$2))/d11B!D21-E$2))) -> #NUM! | V12: =MROUND(G12,10) -> 14310 | W12: =VLOOKUP(V12,'co2'!A$7:E$9999,4,0) -> 213.1 | X12: =VLOOKUP(V12,'co2'!A$7:E$9999,5,0) -> 7.5 | Y12: =W12-L12 -> 452.69652 | Z12: =(M12^2+X12^2)^0.5 -> 10.027016 | AD12: 20180709 | AE12: 98 | AF12: 17.964582 | AG12: 12.056273 | AH12: 0.3203902 | AI12: 3.5787473 | AJ12: 0.042944968
A13: 20221219 | B13: 75 | D13: 15.864672 | F13: 0.14 | G13: =VLOOKUP(B13,'14C'!B$3:L$47,4,0) -> 14734.3 | H13: =VLOOKUP(B13,'14C'!B$3:L$47,5) -> 396.70918 | I13: =VLOOKUP(B13,'14C'!B$3:L$47,7,0) -> 15660 | J13: =VLOOKUP(B13,'14C'!B$3:L$47,8,0) -> 35 | K13: =VLOOKUP(B13,'14C'!B$3:L$47,9,0) -> 204764 | L13: =VLOOKUP(B13,'14C'!B$3:L$47,10,0) -> -153.93184 | M13: =VLOOKUP(B13,'14C'!B$3:L$47,11,0) -> 3.6943845 | N13: =VLOOKUP(MROUND(G13,200),MOT!B$3:C$1502,2)*1 -> -1.1716 | O13: =O10 -> 8.6133156 | P13: =(pKB!G$32-d11B!O13) -> 0.022378326 | Q13: =((D$16-D13)/(E$2-(I$2*D13)-J$2)) -> 0.018139728 | R13: =(((I$2-1)*E$2-J$2)/(D$16-E$2)) -> 1.0968594 | S13: =P13-LOG(1+(Q13*R13)) -> 0.013822126 | T13: =P13-LOG((1+((D13-D$16)/(E$2-(I$2*d11B!D13)-J$2))*(((I$2-1)*(E$2-J$2))/d11B!D22-E$2))) -> -0.2126765 | V13: =MROUND(G13,10) -> 14730 | W13: =VLOOKUP(V13,'co2'!A$7:E$9999,4,0) -> 270.6 | X13: =VLOOKUP(V13,'co2'!A$7:E$9999,5,0) -> 7.5 | Y13: =W13-L13 -> 424.53184 | Z13: =(M13^2+X13^2)^0.5 -> 8.3605309 | AD13: 20180709 | AE13: 101 | AF13: 17.957503 | AG13: 10.124645 | AH13: 0.38114 | AI13: 3.4667576 | AJ13: 0.041601091
A14: 20180711 | B14: 77 | D14: 15.969415 | F14: 0.2538488 | G14: =VLOOKUP(B14,'14C'!B$3:L$47,4,0) -> 15156.9 | H14: =VLOOKUP(B14,'14C'!B$3:L$47,5) -> 424.03061 | I14: =VLOOKUP(B14,'14C'!B$3:L$47,7,0) -> 16775 | J14: =VLOOKUP(B14,'14C'!B$3:L$47,8,0) -> 45 | K14: =VLOOKUP(B14,'14C'!B$3:L$47,9,0) -> 203058 | L14: =VLOOKUP(B14,'14C'!B$3:L$47,10,0) -> -224.95864 | M14: =VLOOKUP(B14,'14C'!B$3:L$47,11,0) -> 4.3538817 | N14: =VLOOKUP(MROUND(G14,200),MOT!B$3:C$1502,2)*1 -> -1.3833 | O14: =pKB!G80 -> 8.6156712 | P14: =(pKB!G$32-d11B!O14) -> 0.020022713 | Q14: =((D$16-D14)/(E$2-(I$2*D14)-J$2)) -> 0.043877447 | R14: =(((I$2-1)*E$2-J$2)/(D$16-E$2)) -> 1.0968594 | S14: =P14-LOG(1+(Q14*R14)) -> -0.00039135726 | T14: =P14-LOG((1+((D14-D$16)/(E$2-(I$2*d11B!D14)-J$2))*(((I$2-1)*(E$2-J$2))/d11B!D23-E$2))) -> -0.41726075 | V14: =MROUND(G14,10) -> 15160 | W14: =VLOOKUP(V14,'co2'!A$7:E$9999,4,0) -> 285.3 | X14: =VLOOKUP(V14,'co2'!A$7:E$9999,5,0) -> 5.9 | Y14: =W14-L14 -> 510.25864 | Z14: =(M14^2+X14^2)^0.5 -> 7.3325498 | AD14: 20180709 | AE14: 104 | AF14: 17.838717 | AG14: 10.951115 | AH14: 0.38114 | AI14: 3.1486918 | AJ14: 0.037784301
A15: 20180711 | B15: 79 | D15: 15.76838 | F15: 0.2557651 | G15: =VLOOKUP(B15,'14C'!B$3:L$47,4,0) -> 15687.2 | H15: =VLOOKUP(B15,'14C'!B$3:L$47,5) -> 433.13776 | I15: =VLOOKUP(B15,'14C'!B$3:L$47,7,0) -> 16550 | J15: =VLOOKUP(B15,'14C'!B$3:L$47,8,0) -> 45 | K15: =VLOOKUP(B15,'14C'!B$3:L$47,9,0) -> 181535 | L15: =VLOOKUP(B15,'14C'!B$3:L$47,10,0) -> -150.13929 | M15: =VLOOKUP(B15,'14C'!B$3:L$47,11,0) -> 4.7741878 | N15: =VLOOKUP(MROUND(G15,200),MOT!B$3:C$1502,2)*1 -> -1.6448 | O15: =pKB!G82 -> 8.6180268 | P15: =(pKB!G$32-d11B!O15) -> 0.0176671 | Q15: =((D$16-D15)/(E$2-(I$2*D15)-J$2)) -> -0.0068117497 | R15: =(((I$2-1)*E$2-J$2)/(D$16-E$2)) -> 1.0968594 | S15: =P15-LOG(1+(Q15*R15)) -> 0.020924127 | T15: =P15-LOG((1+((D15-D$16)/(E$2-(I$2*d11B!D15)-J$2))*(((I$2-1)*(E$2-J$2))/d11B!D24-E$2))) -> 0.15414683 | V15: =MROUND(G15,10) -> 15690 | W15: =VLOOKUP(V15,'co2'!A$7:E$9999,4,0) -> 308 | X15: =VLOOKUP(V15,'co2'!A$7:E$9999,5,0) -> 6 | Y15: =W15-L15 -> 458.13929 | Z15: =(M15^2+X15^2)^0.5 -> 7.6676508 | AD15: 20221219 | AE15: 106 | AF15: 17.578141 | AH15: 0.14 | AI15: 3.3882682 | AJ15: 0.040659218
A16: 20221219 | B16: 92 | D16: 15.794178 | F16: 0.14 | G16: =VLOOKUP(B16,'14C'!B$3:L$47,4,0) -> 18977.8 | H16: =VLOOKUP(B16,'14C'!B$3:L$47,5) -> 466.70918 | I16: =VLOOKUP(B16,'14C'!B$3:L$47,7,0) -> 16800 | J16: =VLOOKUP(B16,'14C'!B$3:L$47,8,0) -> 70 | K16: =VLOOKUP(B16,'14C'!B$3:L$47,9,0) -> 201583 | L16: =VLOOKUP(B16,'14C'!B$3:L$47,10,0) -> 226.58755 | M16: =VLOOKUP(B16,'14C'!B$3:L$47,11,0) -> 10.735257 | N16: =VLOOKUP(MROUND(G16,200),MOT!B$3:C$1502,2)*1 -> -3.1453 | O16: =pKB!G32 -> 8.6356939 | P16: =(pKB!G$32-d11B!O16) -> 0 | Q16: =((D$16-D16)/(E$2-(I$2*D16)-J$2)) -> 0 | R16: =(((I$2-1)*E$2-J$2)/(D$16-E$2)) -> 1.0968594 | S16: =P16-LOG(1+(Q16*R16)) -> 0 | T16: =P16-LOG((1+((D16-D$16)/(E$2-(I$2*d11B!D16)-J$2))*(((I$2-1)*(E$2-J$2))/d11B!D25-E$2))) -> 0 | V16: =MROUND(G16,10) -> 18980 | W16: =VLOOKUP(V16,'co2'!A$7:E$9999,4,0) -> 399.1 | X16: =VLOOKUP(V16,'co2'!A$7:E$9999,5,0) -> 6.3 | Y16: =W16-L16 -> 172.51245 | Z16: =(M16^2+X16^2)^0.5 -> 12.447318 | AD16: 20180709 | AE16: 116 | AF16: 18.160492 | AG16: 32.774228 | AH16: 0.2582063 | AI16: 2.926375 | AJ16: 0.0351165
A17: 20180711 | B17: 94 | D17: 16.143466 | F17: 0.2568596 | G17: =VLOOKUP(B17,'14C'!B$3:L$47,4,0) -> 19670 | H17: =VLOOKUP(B17,'14C'!B$3:L$47,5) -> 460.35714 | I17: =VLOOKUP(B17,'14C'!B$3:L$47,7,0) -> 16960 | J17: =VLOOKUP(B17,'14C'!B$3:L$47,8,0) -> 100 | K17: =VLOOKUP(B17,'14C'!B$3:L$47,9,0) -> 192493 | L17: =VLOOKUP(B17,'14C'!B$3:L$47,10,0) -> 307.4107 | M17: =VLOOKUP(B17,'14C'!B$3:L$47,11,0) -> 16.377223 | N17: =VLOOKUP(MROUND(G17,200),MOT!B$3:C$1502,2)*1 -> -2.4207 | O17: =pKB!G35 -> 8.6274492 | P17: =(pKB!G$32-d11B!O17) -> 0.0082446464 | Q17: =((D$16-D17)/(E$2-(I$2*D17)-J$2)) -> 0.083710638 | R17: =(((I$2-1)*E$2-J$2)/(D$16-E$2)) -> 1.0968594 | S17: =P17-LOG(1+(Q17*R17)) -> -0.029905921 | T17: =P17-LOG((1+((D17-D$16)/(E$2-(I$2*d11B!D17)-J$2))*(((I$2-1)*(E$2-J$2))/d11B!D26-E$2))) -> -0.62663363 | V17: =MROUND(G17,10) -> 19670 | W17: =VLOOKUP(V17,'co2'!A$7:E$9999,4,0) -> 404.5 | X17: =VLOOKUP(V17,'co2'!A$7:E$9999,5,0) -> 8.1 | Y17: =W17-L17 -> 97.089298 | Z17: =(M17^2+X17^2)^0.5 -> 18.270836 | AD17: 20221219 | AE17: 116 | AF17: 17.821481 | AH17: 0.14 | AI17: 3.1725144 | AJ17: 0.038070172
A18: 20180711 | B18: 97 | D18: 15.125516 | F18: 0.2570814 | G18: =VLOOKUP(B18,'14C'!B$3:L$47,4,0) -> 22709.2 | H18: =VLOOKUP(B18,'14C'!B$3:L$47,5) -> 319.77041 | I18: =VLOOKUP(B18,'14C'!B$3:L$47,7,0) -> 19580 | J18: =VLOOKUP(B18,'14C'!B$3:L$47,8,0) -> 670 | K18: =VLOOKUP(B18,'14C'!B$3:L$47,9,0) -> 200178 | L18: =VLOOKUP(B18,'14C'!B$3:L$47,10,0) -> 362.77675 | M18: =VLOOKUP(B18,'14C'!B$3:L$47,11,0) -> 118.53838 | N18: =VLOOKUP(MROUND(G18,200),MOT!B$3:C$1502,2)*1 -> -2.8376 | O18: =pKB!G33 -> 8.6321605 | P18: =(pKB!G$32-d11B!O18) -> 0.0035334199 | Q18: =((D$16-D18)/(E$2-(I$2*D18)-J$2)) -> -0.21383984 | R18: =(((I$2-1)*E$2-J$2)/(D$16-E$2)) -> 1.0968594 | S18: =P18-LOG(1+(Q18*R18)) -> 0.11961786 | T18: =P18-LOG((1+((D18-D$16)/(E$2-(I$2*d11B!D18)-J$2))*(((I$2-1)*(E$2-J$2))/d11B!D27-E$2))) -> #NUM! | V18: =MROUND(G18,10) -> 22710 | W18: =VLOOKUP(V18,'co2'!A$7:E$9999,4,0) -> 504.5 | X18: =VLOOKUP(V18,'co2'!A$7:E$9999,5,0) -> 9.3 | Y18: =W18-L18 -> 141.72325 | Z18: =(M18^2+X18^2)^0.5 -> 118.90264
A19: 20180711 | B19: 98 | D19: 15.96309 | F19: 0.2532235 | G19: =VLOOKUP(B19,'14C'!B$3:L$47,4,0) -> 22898.9 | H19: =VLOOKUP(B19,'14C'!B$3:L$47,5) -> 302.52551 | I19: =VLOOKUP(B19,'14C'!B$3:L$47,7,0) -> 20240 | J19: =VLOOKUP(B19,'14C'!B$3:L$47,8,0) -> 260 | K19: =VLOOKUP(B19,'14C'!B$3:L$47,9,0) -> 200181 | L19: =VLOOKUP(B19,'14C'!B$3:L$47,10,0) -> 284.42341 | M19: =VLOOKUP(B19,'14C'!B$3:L$47,11,0) -> 42.252367 | N19: =VLOOKUP(MROUND(G19,200),MOT!B$3:C$1502,2)*1 -> -2.8376 | O19: =O18 -> 8.6321605 | P19: =(pKB!G$32-d11B!O19) -> 0.0035334199 | Q19: =((D$16-D19)/(E$2-(I$2*D19)-J$2)) -> 0.042362724 | R19: =(((I$2-1)*E$2-J$2)/(D$16-E$2)) -> 1.0968594 | S19: =P19-LOG(1+(Q19*R19)) -> -0.016191682 | T19: =P19-LOG((1+((D19-D$16)/(E$2-(I$2*d11B!D19)-J$2))*(((I$2-1)*(E$2-J$2))/d11B!D28-E$2))) -> -0.42412241 | V19: =MROUND(G19,10) -> 22900 | W19: =VLOOKUP(V19,'co2'!A$7:E$9999,4,0) -> 524.7 | X19: =VLOOKUP(V19,'co2'!A$7:E$9999,5,0) -> 13.5 | Y19: =W19-L19 -> 240.27659 | Z19: =(M19^2+X19^2)^0.5 -> 44.356651
A20: 20180711 | B20: 101 | D20: 15.767705 | F20: 0.2538488 | G20: =VLOOKUP(B20,'14C'!B$3:L$47,4,0) -> 23438.1 | H20: =VLOOKUP(B20,'14C'!B$3:L$47,5) -> 255.20408 | I20: =VLOOKUP(B20,'14C'!B$3:L$47,7,0) -> 20630 | J20: =VLOOKUP(B20,'14C'!B$3:L$47,8,0) -> 80 | K20: =VLOOKUP(B20,'14C'!B$3:L$47,9,0) -> 181554 | L20: =VLOOKUP(B20,'14C'!B$3:L$47,10,0) -> 306.01871 | M20: =VLOOKUP(B20,'14C'!B$3:L$47,11,0) -> 13.071516 | N20: =VLOOKUP(MROUND(G20,200),MOT!B$3:C$1502,2)*1 -> -2.8376 | O20: =O19 -> 8.6321605 | P20: =(pKB!G$32-d11B!O20) -> 0.0035334199 | Q20: =((D$16-D20)/(E$2-(I$2*D20)-J$2)) -> -0.0069912797 | R20: =(((I$2-1)*E$2-J$2)/(D$16-E$2)) -> 1.0968594 | S20: =P20-LOG(1+(Q20*R20)) -> 0.0068766207 | T20: =P20-LOG((1+((D20-D$16)/(E$2-(I$2*d11B!D20)-J$2))*(((I$2-1)*(E$2-J$2))/d11B!D29-E$2))) -> #DIV/0! | V20: =MROUND(G20,10) -> 23440 | W20: =VLOOKUP(V20,'co2'!A$7:E$9999,4,0) -> 494.4 | X20: =VLOOKUP(V20,'co2'!A$7:E$9999,5,0) -> 10.6 | Y20: =W20-L20 -> 188.38129 | Z20: =(M20^2+X20^2)^0.5 -> 16.829276
A21: 20180711 | B21: 104 | D21: 16.007533 | F21: 0.2657288 | G21: =VLOOKUP(B21,'14C'!B$3:L$47,4,0) -> 24297.8 | H21: =VLOOKUP(B21,'14C'!B$3:L$47,5) -> 296.37755 | I21: =VLOOKUP(B21,'14C'!B$3:L$47,7,0) -> 21520 | J21: =VLOOKUP(B21,'14C'!B$3:L$47,8,0) -> 80 | K21: =VLOOKUP(B21,'14C'!B$3:L$47,9,0) -> 176294 | L21: =VLOOKUP(B21,'14C'!B$3:L$47,10,0) -> 297.16635 | M21: =VLOOKUP(B21,'14C'!B$3:L$47,11,0) -> 12.982916 | N21: =VLOOKUP(MROUND(G21,200),MOT!B$3:C$1502,2)*1 -> -2.8376 | O21: =O20 -> 8.6321605 | P21: =(pKB!G$32-d11B!O21) -> 0.0035334199 | Q21: =((D$16-D21)/(E$2-(I$2*D21)-J$2)) -> 0.052903209 | R21: =(((I$2-1)*E$2-J$2)/(D$16-E$2)) -> 1.0968594 | S21: =P21-LOG(1+(Q21*R21)) -> -0.020963487 | T21: =P21-LOG((1+((D21-D$16)/(E$2-(I$2*d11B!D21)-J$2))*(((I$2-1)*(E$2-J$2))/d11B!D30-E$2))) -> #DIV/0! | V21: =MROUND(G21,10) -> 24300 | W21: =VLOOKUP(V21,'co2'!A$7:E$9999,4,0) -> 509.5 | X21: =VLOOKUP(V21,'co2'!A$7:E$9999,5,0) -> 12.2 | Y21: =W21-L21 -> 212.33365 | Z21: =(M21^2+X21^2)^0.5 -> 17.815614
A22: 20221219 | B22: 106 | D22: 15.725713 | F22: 0.14 | G22: 24880 | H22: 363.5 | I22: 22570 | J22: 80 | K22: 208195 | L22: 221.27563 | M22: 12.22335 | N22: =VLOOKUP(MROUND(G22,200),MOT!B$3:C$1502,2)*1 -> -2.8376 | O22: =O21 -> 8.6321605 | P22: =(pKB!G$32-d11B!O22) -> 0.0035334199 | Q22: =((D$16-D22)/(E$2-(I$2*D22)-J$2)) -> -0.018289275 | R22: =(((I$2-1)*E$2-J$2)/(D$16-E$2)) -> 1.0968594 | S22: =P22-LOG(1+(Q22*R22)) -> 0.012334273 | T22: =P22-LOG((1+((D22-D$16)/(E$2-(I$2*d11B!D22)-J$2))*(((I$2-1)*(E$2-J$2))/d11B!D31-E$2))) -> #DIV/0! | U22: New 14C measurement | V22: =MROUND(G22,10) -> 24880 | W22: =VLOOKUP(V22,'co2'!A$7:E$9999,4,0) -> 560.6 | X22: =VLOOKUP(V22,'co2'!A$7:E$9999,5,0) -> 8.6 | Y22: =W22-L22 -> 339.32437 | Z22: =(M22^2+X22^2)^0.5 -> 14.945578
A23: 20180711 | B23: 116 | D23: 15.907341 | E23: size_flag | F23: 0.6527902 | G23: =VLOOKUP(B23,'14C'!B$3:L$47,4,0) -> 27914.6 | H23: =VLOOKUP(B23,'14C'!B$3:L$47,5) -> 650.15306 | I23: =VLOOKUP(B23,'14C'!B$3:L$47,7,0) -> 27020 | J23: =VLOOKUP(B23,'14C'!B$3:L$47,8,0) -> 190 | K23: =VLOOKUP(B23,'14C'!B$3:L$47,9,0) -> 206080 | L23: =VLOOKUP(B23,'14C'!B$3:L$47,10,0) -> 13.08986 | M23: =VLOOKUP(B23,'14C'!B$3:L$47,11,0) -> 24.247669 | N23: =VLOOKUP(MROUND(G23,200),MOT!B$3:C$1502,2)*1 -> -2.8376 | O23: =O22 -> 8.6321605 | P23: =(pKB!G$32-d11B!O23) -> 0.0035334199 | Q23: =((D$16-D23)/(E$2-(I$2*D23)-J$2)) -> 0.028794591 | R23: =(((I$2-1)*E$2-J$2)/(D$16-E$2)) -> 1.0968594 | S23: =P23-LOG(1+(Q23*R23)) -> -0.0099710166 | T23: =P23-LOG((1+((D23-D$16)/(E$2-(I$2*d11B!D23)-J$2))*(((I$2-1)*(E$2-J$2))/d11B!D32-E$2))) -> #DIV/0! | U23: Did I publish this before? | V23: =MROUND(G23,20) -> 27920 | W23: =VLOOKUP(V23,'co2'!A$7:E$9999,4,0) -> 491.4 | X23: =VLOOKUP(V23,'co2'!A$7:E$9999,5,0) -> 14.4 | Y23: =W23-L23 -> 478.31014 | Z23: =(M23^2+X23^2)^0.5 -> 28.201231
A24: 20221219 | B24: 116 | D24: 15.824323 | F24: 0.14 | G24: =VLOOKUP(B24,'14C'!B$3:L$47,4,0) -> 27914.6 | H24: =VLOOKUP(B24,'14C'!B$3:L$47,5) -> 650.15306 | I24: =VLOOKUP(B24,'14C'!B$3:L$47,7,0) -> 27020 | J24: =VLOOKUP(B24,'14C'!B$3:L$47,8,0) -> 190 | K24: =VLOOKUP(B24,'14C'!B$3:L$47,9,0) -> 206080 | L24: =VLOOKUP(B24,'14C'!B$3:L$47,10,0) -> 13.08986 | M24: =VLOOKUP(B24,'14C'!B$3:L$47,11,0) -> 24.247669 | N24: =VLOOKUP(MROUND(G24,200),MOT!B$3:C$1502,2)*1 -> -2.8376 | O24: =O23 -> 8.6321605 | P24: =(pKB!G$32-d11B!O24) -> 0.0035334199 | Q24: =((D$16-D24)/(E$2-(I$2*D24)-J$2)) -> 0.0078406717 | R24: =(((I$2-1)*E$2-J$2)/(D$16-E$2)) -> 1.0968594 | S24: =P24-LOG(1+(Q24*R24)) -> -0.00018559313 | T24: =P24-LOG((1+((D24-D$16)/(E$2-(I$2*d11B!D24)-J$2))*(((I$2-1)*(E$2-J$2))/d11B!E33-E$2))) -> #DIV/0! | U24: Did I publish this before? | V24: =MROUND(G24,20) -> 27920 | W24: =VLOOKUP(V24,'co2'!A$7:E$9999,4,0) -> 491.4 | X24: =VLOOKUP(V24,'co2'!A$7:E$9999,5,0) -> 14.4 | Y24: =W24-L24 -> 478.31014 | Z24: =(M24^2+X24^2)^0.5 -> 28.201231
A25: 20221219 | B25: 121 | D25: 15.946716 | F25: 0.14 | G25: 30568.5 | H25: 1067.5 | I25: 28880 | J25: 550 | K25: 233855 | L25: 32.790594 | M25: 73.189632 | N25: =VLOOKUP(MROUND(G25,200),MOT!B$3:C$1502,2)*1 -> -2.8376 | O25: =O24 -> 8.6321605 | P25: =(pKB!G$32-d11B!O25) -> 0.0035334199 | Q25: =((D$16-D25)/(E$2-(I$2*D25)-J$2)) -> 0.038418336 | R25: =(((I$2-1)*E$2-J$2)/(D$16-E$2)) -> 1.0968594 | S25: =P25-LOG(1+(Q25*R25)) -> -0.014392442 | T25: =P25-LOG((1+((D25-D$16)/(E$2-(I$2*d11B!D25)-J$2))*(((I$2-1)*(E$2-J$2))/d11B!E34-E$2))) -> #DIV/0! | U25: New 14C measurement | V25: =MROUND(G25,20) -> 30560 | W25: =VLOOKUP(V25,'co2'!A$7:E$9999,4,0) -> 521.7 | X25: =VLOOKUP(V25,'co2'!A$7:E$9999,5,0) -> 12.8 | Y25: =W25-L25 -> 488.90941 | Z25: =(M25^2+X25^2)^0.5 -> 74.300487
A26: 20221219 | B26: 121 | D26: 15.725146 | F26: 0.14 | G26: 30568.5 | H26: 1067.5 | I26: 28880 | J26: 550 | K26: 233855 | L26: 32.790594 | M26: 73.189632 | N26: =VLOOKUP(MROUND(G26,200),MOT!B$3:C$1502,2)*1 -> -2.8376 | O26: =O25 -> 8.6321605 | P26: =(pKB!G$32-d11B!O26) -> 0.0035334199 | Q26: =((D$16-D26)/(E$2-(I$2*D26)-J$2)) -> -0.018443542 | R26: =(((I$2-1)*E$2-J$2)/(D$16-E$2)) -> 1.0968594 | S26: =P26-LOG(1+(Q26*R26)) -> 0.01240927 | T26: =P26-LOG((1+((D26-D$16)/(E$2-(I$2*d11B!D26)-J$2))*(((I$2-1)*(E$2-J$2))/d11B!E35-E$2))) -> #DIV/0! | U26: New 14C measurement | V26: =MROUND(G26,20) -> 30560 | W26: =VLOOKUP(V26,'co2'!A$7:E$9999,4,0) -> 521.7 | X26: =VLOOKUP(V26,'co2'!A$7:E$9999,5,0) -> 12.8 | Y26: =W26-L26 -> 488.90941 | Z26: =(M26^2+X26^2)^0.5 -> 74.300487
A27: 20221219 | B27: 122 | D27: 15.621291 | F27: 0.14 | G27: 31426 | H27: 1187 | I27: 28440 | J27: 420 | K27: 176317 | L27: 298.20574 | M27: 69.681567 | N27: =VLOOKUP(MROUND(G27,200),MOT!B$3:C$1502,2)*1 -> -2.8376 | O27: =O26 -> 8.6321605 | P27: =(pKB!G$32-d11B!O27) -> 0.0035334199 | Q27: =((D$16-D27)/(E$2-(I$2*D27)-J$2)) -> -0.047546178 | R27: =(((I$2-1)*E$2-J$2)/(D$16-E$2)) -> 1.0968594 | S27: =P27-LOG(1+(Q27*R27)) -> 0.02679448 | T27: =P27-LOG((1+((D27-D$16)/(E$2-(I$2*d11B!D27)-J$2))*(((I$2-1)*(E$2-J$2))/d11B!E36-E$2))) -> #DIV/0! | U27: New 14C measurement | V27: =MROUND(G27,20) -> 31420 | W27: =VLOOKUP(V27,'co2'!A$7:E$9999,4,0) -> 456.2 | X27: =VLOOKUP(V27,'co2'!A$7:E$9999,5,0) -> 14.8 | Y27: =W27-L27 -> 157.99426 | Z27: =(M27^2+X27^2)^0.5 -> 71.235952
A28: 20180711 | B28: 130 | D28: 15.18813 | F28: 0.4267899 | G28: 34691.5 | H28: 458.5 | I28: 30670 | J28: 760 | K28: 177344 | L28: 459.9212 | M28: 144.86766 | N28: =VLOOKUP(MROUND(G28,200),MOT!B$3:C$1502,2)*1 -> -2.8376 | O28: =O27 -> 8.6321605 | P28: =(pKB!G$32-d11B!O28) -> 0.0035334199 | Q28: =((D$16-D28)/(E$2-(I$2*D28)-J$2)) -> -0.18990935 | R28: =(((I$2-1)*E$2-J$2)/(D$16-E$2)) -> 1.0968594 | S28: =P28-LOG(1+(Q28*R28)) -> 0.10497489 | T28: =P28-LOG((1+((D28-D$16)/(E$2-(I$2*d11B!D28)-J$2))*(((I$2-1)*(E$2-J$2))/d11B!E37-E$2))) -> #DIV/0! | U28: New 14C measurement | V28: =MROUND(G28,20) -> 34700 | W28: =VLOOKUP(V28,'co2'!A$7:E$9999,4,0) -> 508.1 | X28: =VLOOKUP(V28,'co2'!A$7:E$9999,5,0) -> 22.6 | Y28: =W28-L28 -> 48.178797 | Z28: =(M28^2+X28^2)^0.5 -> 146.61991
A32: planktic foram G. bulloides
A33: analysis_date | B33: depth | D33: d11B | F33: d11B_2sigma
A34: 20180709 | B34: 72 | D34: 17.787443 | F34: 0.2913634 | G34: =VLOOKUP(B34,'14C'!B$3:L$47,4,0) -> 14108.9 | H34: =VLOOKUP(B34,'14C'!B$3:L$47,5) -> 350.7398 | I34: =VLOOKUP(B34,'14C'!B$3:L$47,7,0) -> 17080 | J34: =VLOOKUP(B34,'14C'!B$3:L$47,8,0) -> 330 | K34: =VLOOKUP(B34,'14C'!B$3:L$47,9,0) -> 203478 | L34: =VLOOKUP(B34,'14C'!B$3:L$47,10,0) -> -342.67476 | M34: =VLOOKUP(B34,'14C'!B$3:L$47,11,0)*1 -> 27.565606 | N34: =VLOOKUP(MROUND(G34,200),MOT!B$3:C$1502,2)*1 -> -1.2533 | O34: =O11 -> 8.6144934 | P34: =(pKB!G$32-d11B!O34) -> 0.021200519 | Q34: =((D$42-D34)/(E$2-(I$2*D34)-J$2)) -> 0.035709367 | R34: =(((I$2-1)*E$2-J$2)/(D$16-E$2)) -> 1.0968594 | S34: =P34-LOG(1+(Q34*R34)) -> 0.0045146902 | V34: =MROUND(G34,20) -> 14100 | W34: =VLOOKUP(V34,'co2'!A$7:E$9999,4,0) -> 201.2 | X34: =VLOOKUP(V34,'co2'!A$7:E$9999,5,0) -> 3.6 | Y34: =W34-L34 -> 543.87476 | Z34: =(M34^2+X34^2)^0.5 -> 27.799688
A35: 20180709 | B35: 73 | D35: 18.220424 | F35: 0.3203902 | G35: =VLOOKUP(B35,'14C'!B$3:L$47,4,0) -> 14314.9 | H35: =VLOOKUP(B35,'14C'!B$3:L$47,5) -> 368.41837 | I35: =VLOOKUP(B35,'14C'!B$3:L$47,7,0) -> 16110 | J35: =VLOOKUP(B35,'14C'!B$3:L$47,8,0) -> 70 | K35: =VLOOKUP(B35,'14C'!B$3:L$47,9,0) -> 203480 | L35: =VLOOKUP(B35,'14C'!B$3:L$47,10,0) -> -239.59652 | M35: =VLOOKUP(B35,'14C'!B$3:L$47,11,0)*1 -> 6.6551519 | N35: =VLOOKUP(MROUND(G35,200),MOT!B$3:C$1502,2)*1 -> -1.0909 | O35: =O12 -> 8.6121377 | P35: =(pKB!G$32-d11B!O35) -> 0.023556133 | Q35: =((D$42-D35)/(E$2-(I$2*D35)-J$2)) -> 0.10185244 | R35: =(((I$2-1)*E$2-J$2)/(D$16-E$2)) -> 1.0968594 | S35: =P35-LOG(1+(Q35*R35)) -> -0.022438427 | V35: =MROUND(G35,20) -> 14320 | W35: =VLOOKUP(V35,'co2'!A$7:E$9999,4,0) -> 212.8 | X35: =VLOOKUP(V35,'co2'!A$7:E$9999,5,0) -> 6.5 | Y35: =W35-L35 -> 452.39652 | Z35: =(M35^2+X35^2)^0.5 -> 9.3027441
A36: 20180709 | B36: 79 | D36: 17.897187 | F36: 0.4147743 | G36: =VLOOKUP(B36,'14C'!B$3:L$47,4,0) -> 15687.2 | H36: =VLOOKUP(B36,'14C'!B$3:L$47,5) -> 433.13776 | I36: =VLOOKUP(B36,'14C'!B$3:L$47,7,0) -> 16550 | J36: =VLOOKUP(B36,'14C'!B$3:L$47,8,0) -> 45 | K36: =VLOOKUP(B36,'14C'!B$3:L$47,9,0) -> 181535 | L36: =VLOOKUP(B36,'14C'!B$3:L$47,10,0) -> -150.13929 | M36: =VLOOKUP(B36,'14C'!B$3:L$47,11,0)*1 -> 4.7741878 | N36: =VLOOKUP(MROUND(G36,200),MOT!B$3:C$1502,2)*1 -> -1.6448 | O36: =O15 -> 8.6180268 | P36: =(pKB!G$32-d11B!O36) -> 0.0176671 | Q36: =((D$42-D36)/(E$2-(I$2*D36)-J$2)) -> 0.05340579 | R36: =(((I$2-1)*E$2-J$2)/(D$16-E$2)) -> 1.0968594 | S36: =P36-LOG(1+(Q36*R36)) -> -0.0070560275 | V36: =MROUND(G36,20) -> 15680 | W36: =VLOOKUP(V36,'co2'!A$7:E$9999,4,0) -> 307.7 | X36: =VLOOKUP(V36,'co2'!A$7:E$9999,5,0) -> 5.9 | Y36: =W36-L36 -> 457.83929 | Z36: =(M36^2+X36^2)^0.5 -> 7.5896554
A37: 20221219 | B37: 87 | D37: 17.975221 | F37: 0.14 | G37: =VLOOKUP(B37,'14C'!B$3:L$47,4,0) -> 17231.5 | H37: =VLOOKUP(B37,'14C'!B$3:L$47,5) -> 324.13265 | I37: =VLOOKUP(B37,'14C'!B$3:L$47,7,0) -> 17615 | J37: =VLOOKUP(B37,'14C'!B$3:L$47,8,0) -> 50 | K37: =VLOOKUP(B37,'14C'!B$3:L$47,9,0) -> 181536 | L37: =VLOOKUP(B37,'14C'!B$3:L$47,10,0) -> -102.7834 | M37: =VLOOKUP(B37,'14C'!B$3:L$47,11,0)*1 -> 5.6019836 | N37: =VLOOKUP(MROUND(G37,200),MOT!B$3:C$1502,2)*1 -> -2.8449 | O37: =O18 -> 8.6321605 | P37: =(pKB!G$32-d11B!O37) -> 0.0035334199 | Q37: =((D$42-D37)/(E$2-(I$2*D37)-J$2)) -> 0.065588097 | R37: =(((I$2-1)*E$2-J$2)/(D$16-E$2)) -> 1.0968594 | S37: =P37-LOG(1+(Q37*R37)) -> -0.02663743 | V37: =MROUND(G37,20) -> 17240 | W37: =VLOOKUP(V37,'co2'!A$7:E$9999,4,0) -> 382.9 | X37: =VLOOKUP(V37,'co2'!A$7:E$9999,5,0) -> 7.9 | Y37: =W37-L37 -> 485.6834 | Z37: =(M37^2+X37^2)^0.5 -> 9.6846383
A38: 20180709 | B38: 97 | G38: =VLOOKUP(B38,'14C'!B$3:L$47,4,0) -> 22709.2 | H38: =VLOOKUP(B38,'14C'!B$3:L$47,5) -> 319.77041 | I38: =VLOOKUP(B38,'14C'!B$3:L$47,7,0) -> 19580 | J38: =VLOOKUP(B38,'14C'!B$3:L$47,8,0) -> 670 | K38: =VLOOKUP(B38,'14C'!B$3:L$47,9,0) -> 200178 | L38: =VLOOKUP(B38,'14C'!B$3:L$47,10,0) -> 362.77675 | M38: =VLOOKUP(B38,'14C'!B$3:L$47,11,0)*1 -> 118.53838 | N38: =VLOOKUP(MROUND(G38,200),MOT!B$3:C$1502,2)*1 -> -2.8376 | O38: =O37 -> 8.6321605 | P38: =(pKB!G$32-d11B!O38) -> 0.0035334199 | Q38: =((D$42-D38)/(E$2-(I$2*D38)-J$2)) -> 1.4164497 | R38: =(((I$2-1)*E$2-J$2)/(D$16-E$2)) -> 1.0968594 | V38: =MROUND(G38,20) -> 22700 | W38: =VLOOKUP(V38,'co2'!A$7:E$9999,4,0) -> 502.8 | X38: =VLOOKUP(V38,'co2'!A$7:E$9999,5,0) -> 9.1 | Y38: =W38-L38 -> 140.02325 | Z38: =(M38^2+X38^2)^0.5 -> 118.88717
A39: 20180709 | B39: 98 | D39: 17.964582 | F39: 0.3203902 | G39: =VLOOKUP(B39,'14C'!B$3:L$47,4,0) -> 22898.9 | H39: =VLOOKUP(B39,'14C'!B$3:L$47,5) -> 302.52551 | I39: =VLOOKUP(B39,'14C'!B$3:L$47,7,0) -> 20240 | J39: =VLOOKUP(B39,'14C'!B$3:L$47,8,0) -> 260 | K39: =VLOOKUP(B39,'14C'!B$3:L$47,9,0) -> 200181 | L39: =VLOOKUP(B39,'14C'!B$3:L$47,10,0) -> 284.42341 | M39: =VLOOKUP(B39,'14C'!B$3:L$47,11,0)*1 -> 42.252367 | N39: =VLOOKUP(MROUND(G39,200),MOT!B$3:C$1502,2)*1 -> -2.8376 | O39: =O38 -> 8.6321605 | P39: =(pKB!G$32-d11B!O39) -> 0.0035334199 | Q39: =((D$42-D39)/(E$2-(I$2*D39)-J$2)) -> 0.063946301 | R39: =(((I$2-1)*E$2-J$2)/(D$16-E$2)) -> 1.0968594 | S39: =P39-LOG(1+(Q39*R39)) -> -0.025907218 | V39: =MROUND(G39,20) -> 22900 | W39: =VLOOKUP(V39,'co2'!A$7:E$9999,4,0) -> 524.7 | X39: =VLOOKUP(V39,'co2'!A$7:E$9999,5,0) -> 13.5 | Y39: =W39-L39 -> 240.27659 | Z39: =(M39^2+X39^2)^0.5 -> 44.356651
A40: 20180709 | B40: 101 | D40: 17.957503 | F40: 0.38114 | G40: =VLOOKUP(B40,'14C'!B$3:L$47,4,0) -> 23438.1 | H40: =VLOOKUP(B40,'14C'!B$3:L$47,5) -> 255.20408 | I40: =VLOOKUP(B40,'14C'!B$3:L$47,7,0) -> 20630 | J40: =VLOOKUP(B40,'14C'!B$3:L$47,8,0) -> 80 | K40: =VLOOKUP(B40,'14C'!B$3:L$47,9,0) -> 181554 | L40: =VLOOKUP(B40,'14C'!B$3:L$47,10,0) -> 306.01871 | M40: =VLOOKUP(B40,'14C'!B$3:L$47,11,0)*1 -> 13.071516 | N40: =VLOOKUP(MROUND(G40,200),MOT!B$3:C$1502,2)*1 -> -2.8376 | O40: =O39 -> 8.6321605 | P40: =(pKB!G$32-d11B!O40) -> 0.0035334199 | Q40: =((D$42-D40)/(E$2-(I$2*D40)-J$2)) -> 0.062850455 | R40: =(((I$2-1)*E$2-J$2)/(D$16-E$2)) -> 1.0968594 | S40: =P40-LOG(1+(Q40*R40)) -> -0.025419141 | V40: =MROUND(G40,20) -> 23440 | W40: =VLOOKUP(V40,'co2'!A$7:E$9999,4,0) -> 494.4 | X40: =VLOOKUP(V40,'co2'!A$7:E$9999,5,0) -> 10.6 | Y40: =W40-L40 -> 188.38129 | Z40: =(M40^2+X40^2)^0.5 -> 16.829276
A41: 20180709 | B41: 104 | D41: 17.838717 | F41: 0.38114 | G41: =VLOOKUP(B41,'14C'!B$3:L$47,4,0) -> 24297.8 | H41: =VLOOKUP(B41,'14C'!B$3:L$47,5) -> 296.37755 | I41: =VLOOKUP(B41,'14C'!B$3:L$47,7,0) -> 21520 | J41: =VLOOKUP(B41,'14C'!B$3:L$47,8,0) -> 80 | K41: =VLOOKUP(B41,'14C'!B$3:L$47,9,0) -> 176294 | L41: =VLOOKUP(B41,'14C'!B$3:L$47,10,0) -> 297.16635 | M41: =VLOOKUP(B41,'14C'!B$3:L$47,11,0)*1 -> 12.982916 | N41: =VLOOKUP(MROUND(G41,200),MOT!B$3:C$1502,2)*1 -> -2.8376 | O41: =O40 -> 8.6321605 | P41: =(pKB!G$32-d11B!O41) -> 0.0035334199 | Q41: =((D$42-D41)/(E$2-(I$2*D41)-J$2)) -> 0.044061476 | R41: =(((I$2-1)*E$2-J$2)/(D$16-E$2)) -> 1.0968594 | S41: =P41-LOG(1+(Q41*R41)) -> -0.016964281 | V41: =MROUND(G41,20) -> 24300 | W41: =VLOOKUP(V41,'co2'!A$7:E$9999,4,0) -> 509.5 | X41: =VLOOKUP(V41,'co2'!A$7:E$9999,5,0) -> 12.2 | Y41: =W41-L41 -> 212.33365 | Z41: =(M41^2+X41^2)^0.5 -> 17.815614
A42: 20221219 | B42: 106 | D42: 17.578141 | F42: 0.14 | G42: 24880 | H42: =VLOOKUP(B42,'14C'!B$3:L$47,5) -> 296.37755 | I42: 21810 | J42: 210 | K42: 176293 | L42: 263.36942 | M42: 33.462698 | N42: =VLOOKUP(MROUND(G42,200),MOT!B$3:C$1502,2)*1 -> -2.8376 | O42: =O41 -> 8.6321605 | P42: =(pKB!G$32-d11B!O42) -> 0.0035334199 | Q42: =((D$42-D42)/(E$2-(I$2*D42)-J$2)) -> 0 | R42: =(((I$2-1)*E$2-J$2)/(D$16-E$2)) -> 1.0968594 | S42: =P42-LOG(1+(Q42*R42)) -> 0.0035334199 | V42: =MROUND(G42,20) -> 24880 | W42: =VLOOKUP(V42,'co2'!A$7:E$9999,4,0) -> 560.6 | X42: =VLOOKUP(V42,'co2'!A$7:E$9999,5,0) -> 8.6 | Y42: =W42-L42 -> 297.23058 | Z42: =(M42^2+X42^2)^0.5 -> 34.55014
A43: 20180709 | B43: 116 | D43: 18.160492 | F43: 0.2582063 | G43: =VLOOKUP(B43,'14C'!B$3:L$47,4,0) -> 27914.6 | H43: =VLOOKUP(B43,'14C'!B$3:L$47,5) -> 650.15306 | I43: =VLOOKUP(B43,'14C'!B$3:L$47,7,0) -> 27020 | J43: =VLOOKUP(B43,'14C'!B$3:L$47,8,0) -> 190 | K43: =VLOOKUP(B43,'14C'!B$3:L$47,9,0) -> 206080 | L43: =VLOOKUP(B43,'14C'!B$3:L$47,10,0) -> 13.08986 | M43: =VLOOKUP(B43,'14C'!B$3:L$47,11,0)*1 -> 24.247669 | N43: =VLOOKUP(MROUND(G43,200),MOT!B$3:C$1502,2)*1 -> -2.8376 | O43: =O42 -> 8.6321605 | P43: =(pKB!G$32-d11B!O43) -> 0.0035334199 | Q43: =((D$42-D43)/(E$2-(I$2*D43)-J$2)) -> 0.093258872 | R43: =(((I$2-1)*E$2-J$2)/(D$16-E$2)) -> 1.0968594 | S43: =P43-LOG(1+(Q43*R43)) -> -0.038763184 | V43: =MROUND(G43,20) -> 27920 | W43: =VLOOKUP(V43,'co2'!A$7:E$9999,4,0) -> 491.4 | X43: =VLOOKUP(V43,'co2'!A$7:E$9999,5,0) -> 14.4 | Y43: =W43-L43 -> 478.31014 | Z43: =(M43^2+X43^2)^0.5 -> 28.201231
A44: 20221219 | B44: 116 | D44: 17.821481 | F44: 0.14 | G44: =VLOOKUP(B44,'14C'!B$3:L$47,4,0) -> 27914.6 | H44: =VLOOKUP(B44,'14C'!B$3:L$47,5) -> 650.15306 | I44: =VLOOKUP(B44,'14C'!B$3:L$47,7,0) -> 27020 | J44: =VLOOKUP(B44,'14C'!B$3:L$47,8,0) -> 190 | K44: =VLOOKUP(B44,'14C'!B$3:L$47,9,0) -> 206080 | L44: =VLOOKUP(B44,'14C'!B$3:L$47,10,0) -> 13.08986 | M44: =VLOOKUP(B44,'14C'!B$3:L$47,11,0)*1 -> 24.247669 | N44: =VLOOKUP(MROUND(G44,200),MOT!B$3:C$1502,2)*1 -> -2.8376 | O44: =O43 -> 8.6321605 | P44: =(pKB!G$32-d11B!O44) -> 0.0035334199 | Q44: =((D$42-D44)/(E$2-(I$2*D44)-J$2)) -> 0.041270509 | R44: =(((I$2-1)*E$2-J$2)/(D$16-E$2)) -> 1.0968594 | S44: =P44-LOG(1+(Q44*R44)) -> -0.015694212 | V44: =MROUND(G44,20) -> 27920 | W44: =VLOOKUP(V44,'co2'!A$7:E$9999,4,0) -> 491.4 | X44: =VLOOKUP(V44,'co2'!A$7:E$9999,5,0) -> 14.4 | Y44: =W44-L44 -> 478.31014 | Z44: =(M44^2+X44^2)^0.5 -> 28.201231

Sheet MOT
A1: Age | C1: Mean Spline | D1: Upper bound | E1: Lower bound
A2: yr BP | B2: cal.age.rounded | C2: °C | D2: °C | E2: °C
A3: 6700 | B3: =MROUND(A3,100) -> 6700 | C3: -1.5468 | D3: -1.216 | E3: -1.8777
A4: 6710.1 | B4: =MROUND(A4,100) -> 6700 | C4: -1.5434 | D4: -1.2158 | E4: -1.871
A5: 6720.1 | B5: =MROUND(A5,100) -> 6700 | C5: -1.5399 | D5: -1.2154 | E5: -1.8645
A6: 6730.2 | B6: =MROUND(A6,100) -> 6700 | C6: -1.5365 | D6: -1.2148 | E6: -1.8582
A7: 6740.3 | B7: =MROUND(A7,100) -> 6700 | C7: -1.5331 | D7: -1.2141 | E7: -1.852
A8: 6750.4 | B8: =MROUND(A8,100) -> 6800 | C8: -1.5296 | D8: -1.2132 | E8: -1.8461
A9: 6760.4 | B9: =MROUND(A9,100) -> 6800 | C9: -1.5262 | D9: -1.2121 | E9: -1.8403
A10: 6770.5 | B10: =MROUND(A10,100) -> 6800 | C10: -1.5227 | D10: -1.2108 | E10: -1.8347
A11: 6780.6 | B11: =MROUND(A11,100) -> 6800 | C11: -1.5193 | D11: -1.2094 | E11: -1.8292
A12: 6790.7 | B12: =MROUND(A12,100) -> 6800 | C12: -1.5158 | D12: -1.2077 | E12: -1.824
A13: 6800.7 | B13: =MROUND(A13,100) -> 6800 | C13: -1.5123 | D13: -1.2058 | E13: -1.8189
A14: 6810.8 | B14: =MROUND(A14,100) -> 6800 | C14: -1.5088 | D14: -1.2037 | E14: -1.814
... A1502: 21800 | B1502: =MROUND(A1502,100) -> 21800 | C1502: -2.8376 | D1502: -2.4112 | E1502: -3.2639

Sheet pKB
A1: Delta pH | B1: Delta pKB | C1: - | D1: log10 | E1: d11B SW | F1: d11B SW.err | G1: d11B1 | H1: d11B0 | I1: alpha | J1: epsilon
E2: 39.61 | F2: 4.2 | I2: 1.0272 | J2: 27.2
E19: Km/m (from Dickson 1990) | F19: Rae's pKB value from this (to left)
C20: =LOG(D20)*-1 -> 8.5797481 | D20: =(EXP(E20)) -> 2.6317942e-09 | E20: -19.7556 | F20: 8.579 | G20: =10^(-F20) -> 2.6363314e-09 | H20: =LN(G20) -> -19.753878 | J20: =10^(-8.6) -> 2.5118864e-09 | K20: =LOG(J20) -> -8.6
D21: =LN(E21) -> -0.050618559 | E21: =EXP(1/E20) -> 0.95064122 | F21: =LN(1/F20) -> -2.1493174
D22: =LN(E22) -> 1.093076 | E22: =LN(-E20) -> 2.983437 | F22: =EXP(1/F20) -> 1.1236291
D23: =LN(E23) -> 0.25904354 | E23: =LOG(-E20) -> 1.2956902 | F23: =LOG(F20) -> 0.93343667
E24: =LOG10(-E20) -> 1.2956902
A30: Delta MOT | C30: degrees C | D30: Kelvin | E30: value from Dickson 1990 | G30: pKB
C31: =D31-273 -> 20.15 | D31: 293.15 | E31: -19.8912 | F31: =EXP(E31) -> 2.2980613e-09 | G31: =LOG(F31)*-1 -> 8.6386384
A32: -3.1 | C32: =C34-0.6 -> 20.4 | D32: =273+C32 -> 293.4 | E32: =((D32-D$31)/(D$62-D$31))*(E$62-E$31)+E$31 -> -19.88442 | F32: =EXP(E32) -> 2.3136951e-09 | G32: =LOG(F32)*-1 -> 8.6356939
A33: -2.8 | C33: =C35-0.4 -> 20.7 | D33: =273+C33 -> 293.7 | E33: =((D33-D$31)/(D$62-D$31))*(E$62-E$31)+E$31 -> -19.876284 | F33: =EXP(E33) -> 2.3325961e-09 | G33: =LOG(F33)*-1 -> 8.6321605
A34: -2.5 | B34: 0 | C34: =D34-273 -> 21 | D34: 294 | E34: =((D34-D$31)/(D$62-D$31))*(E$62-E$31)+E$31 -> -19.868148 | F34: =EXP(E34) -> 2.3516515e-09 | G34: =LOG(F34)*-1 -> 8.628627
A35: =A$34+B35 -> -2.4 | B35: 0.1 | C35: =C$34+B35 -> 21.1 | D35: =(C35-C34)+D34 -> 294.1 | E35: =((D35-D$31)/(D$62-D$31))*(E$62-E$31)+E$31 -> -19.865436 | F35: =EXP(E35) -> 2.3580378e-09 | G35: =LOG(F35)*-1 -> 8.6274492
A36: =A$34+B36 -> -2.3 | B36: 0.2 | C36: =C$34+B36 -> 21.2 | D36: =(C36-C35)+D35 -> 294.2 | E36: =((D36-D$31)/(D$62-D$31))*(E$62-E$31)+E$31 -> -19.862724 | F36: =EXP(E36) -> 2.3644415e-09 | G36: =LOG(F36)*-1 -> 8.6262714
A37: =A$34+B37 -> -2.2 | B37: 0.3 | C37: =C$34+B37 -> 21.3 | D37: =(C37-C36)+D36 -> 294.3 | E37: =((D37-D$31)/(D$62-D$31))*(E$62-E$31)+E$31 -> -19.860012 | F37: =EXP(E37) -> 2.3708626e-09 | G37: =LOG(F37)*-1 -> 8.6250936
A38: =A$34+B38 -> -2.1 | B38: 0.4 | C38: =C$34+B38 -> 21.4 | D38: =(C38-C37)+D37 -> 294.4 | E38: =((D38-D$31)/(D$62-D$31))*(E$62-E$31)+E$31 -> -19.8573 | F38: =EXP(E38) -> 2.3773011e-09 | G38: =LOG(F38)*-1 -> 8.6239158
A39: =A$34+B39 -> -2 | B39: 0.5 | C39: =C$34+B39 -> 21.5 | D39: =(C39-C38)+D38 -> 294.5 | E39: =((D39-D$31)/(D$62-D$31))*(E$62-E$31)+E$31 -> -19.854588 | F39: =EXP(E39) -> 2.3837571e-09 | G39: =LOG(F39)*-1 -> 8.622738
A40: =A$34+B40 -> -1.9 | B40: 0.6 | C40: =C$34+B40 -> 21.6 | D40: =(C40-C39)+D39 -> 294.6 | E40: =((D40-D$31)/(D$62-D$31))*(E$62-E$31)+E$31 -> -19.851876 | F40: =EXP(E40) -> 2.3902306e-09 | G40: =LOG(F40)*-1 -> 8.6215602
A41: =A$34+B41 -> -1.8 | B41: 0.7 | C41: =C$34+B41 -> 21.7 | D41: =(C41-C40)+D40 -> 294.7 | E41: =((D41-D$31)/(D$62-D$31))*(E$62-E$31)+E$31 -> -19.849164 | F41: =EXP(E41) -> 2.3967217e-09 | G41: =LOG(F41)*-1 -> 8.6203824
A42: =A$34+B42 -> -1.7 | B42: 0.8 | C42: =C$34+B42 -> 21.8 | D42: =(C42-C41)+D41 -> 294.8 | E42: =((D42-D$31)/(D$62-D$31))*(E$62-E$31)+E$31 -> -19.846452 | F42: =EXP(E42) -> 2.4032304e-09 | G42: =LOG(F42)*-1 -> 8.6192046
A43: =A$34+B43 -> -1.6 | B43: 0.9 | C43: =C$34+B43 -> 21.9 | D43: =(C43-C42)+D42 -> 294.9 | E43: =((D43-D$31)/(D$62-D$31))*(E$62-E$31)+E$31 -> -19.84374 | F43: =EXP(E43) -> 2.4097568e-09 | G43: =LOG(F43)*-1 -> 8.6180268
A44: =A$34+B44 -> -1.5 | B44: 1 | C44: =C$34+B44 -> 22 | D44: =(C44-C43)+D43 -> 295 | E44: =((D44-D$31)/(D$62-D$31))*(E$62-E$31)+E$31 -> -19.841028 | F44: =EXP(E44) -> 2.4163009e-09 | G44: =LOG(F44)*-1 -> 8.616849
A45: =A$34+B45 -> -1.4 | B45: 1.1 | C45: =C$34+B45 -> 22.1 | D45: =(C45-C44)+D44 -> 295.1 | E45: =((D45-D$31)/(D$62-D$31))*(E$62-E$31)+E$31 -> -19.838316 | F45: =EXP(E45) -> 2.4228629e-09 | G45: =LOG(F45)*-1 -> 8.6156712
A46: =A$34+B46 -> -1.3 | B46: 1.2 | C46: =C$34+B46 -> 22.2 | D46: =(C46-C45)+D45 -> 295.2 | E46: =((D46-D$31)/(D$62-D$31))*(E$62-E$31)+E$31 -> -19.835604 | F46: =EXP(E46) -> 2.4294426e-09 | G46: =LOG(F46)*-1 -> 8.6144934
... A58: =A$34+B58 -> -0.1 | B58: 2.4 | C58: =C$34+B58 -> 23.4 | D58: =(C58-C57)+D57 -> 296.4 | E58: =((D58-D$31)/(D$62-D$31))*(E$62-E$31)+E$31 -> -19.80306 | F58: =EXP(E58) -> 2.5098069e-09 | G58: =LOG(F58)*-1 -> 8.6003597
A59: =A$34+B59 -> 0 | B59: 2.5 | C59: 23.5 | D59: =D54+0.5 -> 296.5 | E59: =((D59-D$31)/(D$62-D$31))*(E$62-E$31)+E$31 -> -19.800348 | F59: =EXP(E59) -> 2.5166228e-09 | G59: =LOG(F59)*-1 -> 8.5991819
B60: 3 | C60: =D60-273 -> 24 | D60: 297 | E60: =((D60-D$31)/(D$62-D$31))*(E$62-E$31)+E$31 -> -19.786788 | F60: =EXP(E60) -> 2.5509806e-09 | G60: =LOG(F60)*-1 -> 8.5932928
B61: 4 | C61: =D61-273 -> 25 | D61: 298 | E61: =((D61-D$31)/(D$62-D$31))*(E$62-E$31)+E$31 -> -19.759668 | F61: =EXP(E61) -> 2.6211099e-09 | G61: =LOG(F61)*-1 -> 8.5815148
C62: =D62-273 -> 25.15 | D62: 298.15 | E62: -19.7556 | F62: =EXP(E62) -> 2.6317942e-09 | G62: =LOG(F62)*-1 -> 8.5797481
A66: 0 | B66: 2.5 | C66: 23.5 | D66: 296.5 | E66: -19.800348 | F66: 2.5166228e-09 | G66: 8.5991819
A67: -0.1 | B67: 2.4 | C67: 23.4 | D67: 296.4 | E67: -19.80306 | F67: 2.5098069e-09 | G67: 8.6003597
A68: -0.2 | B68: 2.3 | C68: 23.3 | D68: 296.3 | E68: -19.805772 | F68: 2.5030096e-09 | G68: 8.6015375
A69: -0.3 | B69: 2.2 | C69: 23.2 | D69: 296.2 | E69: -19.808484 | F69: 2.4962306e-09 | G69: 8.6027153
A70: -0.4 | B70: 2.1 | C70: 23.1 | D70: 296.1 | E70: -19.811196 | F70: 2.48947e-09 | G70: 8.6038931
A71: -0.5 | B71: 2 | C71: 23 | D71: 296 | E71: -19.813908 | F71: 2.4827277e-09 | G71: 8.6050709
A72: -0.6 | B72: 1.9 | C72: 22.9 | D72: 295.9 | E72: -19.81662 | F72: 2.4760037e-09 | G72: 8.6062487
A73: -0.7 | B73: 1.8 | C73: 22.8 | D73: 295.8 | E73: -19.819332 | F73: 2.4692978e-09 | G73: 8.6074265
A74: -0.8 | B74: 1.7 | C74: 22.7 | D74: 295.7 | E74: -19.822044 | F74: 2.4626102e-09 | G74: 8.6086043
A75: -0.9 | B75: 1.6 | C75: 22.6 | D75: 295.6 | E75: -19.824756 | F75: 2.4559406e-09 | G75: 8.6097821
...

Sheet co2
A2: ##INTCAL20: Atmospheric data from Reimer et al (2020)
A3: # Reimer et al. 2020
A4: # DOI: 10.2458/azu_js_rc.xx.xxxx
A6: # CAL BP | B6: 14C age | C6: Sigma | D6: Delta 14C | E6: Sigma
A7: 0 | B7: 199 | C7: 11 | D7: -24.5 | E7: 1.4
A8: 1 | B8: 197 | C8: 11 | D8: -24.1 | E8: 1.4
A9: 2 | B9: 195 | C9: 11 | D9: -23.8 | E9: 1.4
A10: 3 | B10: 193 | C10: 11 | D10: -23.3 | E10: 1.4
A11: 4 | B11: 190 | C11: 11 | D11: -22.9 | E11: 1.3
A12: 5 | B12: 188 | C12: 11 | D12: -22.5 | E12: 1.3
A13: 6 | B13: 185 | C13: 11 | D13: -22 | E13: 1.3
A14: 7 | B14: 181 | C14: 11 | D14: -21.5 | E14: 1.3
A15: 8 | B15: 178 | C15: 11 | D15: -20.9 | E15: 1.3
A16: 9 | B16: 174 | C16: 11 | D16: -20.3 | E16: 1.3
A17: 10 | B17: 170 | C17: 11 | D17: -19.7 | E17: 1.3
A18: 11 | B18: 166 | C18: 11 | D18: -19.1 | E18: 1.3
... A9507: 55000 | B9507: 50100 | C9507: 1024 | D9507: 528.5 | E9507: 193.9
